Workbook

Sheet DASHBOARD
A1: DASHBOARD — CAPACIDADE PRODUTIVA | CALDEIRARIA E USINAGEM
B3: Cenário: | C3: Atual | F3: Verde = suficiente | Amarelo = atenção | Vermelho = insuficiente (limites em PARAMETROS C6:C7)
B4: Filtro família: | C4: TODAS
B7: Capacidade disponível (h) | C7: Carga planejada (h) | D7: Utilização | E7: Horas excedentes (h) | F7: Horas ociosas (h) | G7: Func. necessários | H7: Func. disponíveis | I7: Horas extras necessárias (h) | J7: Sogyodo
B8: =SUMPRODUCT($J$13:$J$27,$E$13:$E$27) | C8: =SUMPRODUCT($J$13:$J$27,$F$13:$F$27) | D8: =IF(B8>0,C8/B8,0) | E8: =SUMPRODUCT($J$13:$J$27*($H$13:$H$27<0)*(-$H$13:$H$27)) | F8: =SUMPRODUCT($J$13:$J$27*($H$13:$H$27>0)*$H$13:$H$27) | G8: =H8+SUMPRODUCT($J$13:$J$27,$K$13:$K$27) | H8: =SUMPRODUCT($J$13:$J$27,$D$13:$D$27) | I8: =E8 | J8: =IF(PARAMETROS!$C$8="Nominal",IF(SUMPRODUCT($J$13:$J$27,$L$13:$L$27)>0,C8/SUMPRODUCT($J$13:$J$27,$L$13:$L$27),0),D8)
B9: USINAGEM — capacidade (h) | C9: USINAGEM — carga (h) | D9: USINAGEM — utilização | E9: USINAGEM — horas excedentes (h) | F9: USINAGEM — horas ociosas (h) | G9: USINAGEM — máquinas insuficientes | H9: USINAGEM — máquinas em atenção | I9: USINAGEM — horas extras necessárias (h) | J9: USINAGEM — Sogyodo
B10: =SUM($E$31:$E$36) | C10: =SUM($F$31:$F$36) | D10: =IF(B10>0,C10/B10,0) | E10: =SUMPRODUCT(($H$31:$H$36<0)*(-$H$31:$H$36)) | F10: =SUMPRODUCT(($H$31:$H$36>0)*$H$31:$H$36) | G10: =COUNTIF($I$31:$I$36,"INSUFICIENTE") | H10: =COUNTIF($I$31:$I$36,"ATENÇÃO") | I10: =E10 | J10: =IF(PARAMETROS!$C$8="Nominal",D10*INDEX(PARAMETROS!$C$23:$F$23,PARAMETROS!$C$9)*INDEX(PARAMETROS!$C$24:$F$24,PARAMETROS!$C$9),D10)
A11: CARGA × CAPACIDADE POR CÉLULA
A12: # | B12: Célula | C12: Família | D12: Func. | E12: Capacidade (h) | F12: Carga (h) | G12: Utilização | H12: Saldo (h) | I12: Status | J12: Filtro | K12: Func. adic. | L12: Cap. nominal (h) | M12: Chave
A13: 1 | B13: =INDEX(CAP_CELULA!$C$6:$C$65,(PARAMETROS!$C$9-1)*15+1) | C13: =INDEX(CAP_CELULA!$D$6:$D$65,(PARAMETROS!$C$9-1)*15+1) | D13: =INDEX(CAP_CELULA!$E$6:$E$65,(PARAMETROS!$C$9-1)*15+1) | E13: =INDEX(CAP_CELULA!$G$6:$G$65,(PARAMETROS!$C$9-1)*15+1) | F13: =INDEX(CAP_CELULA!$I$6:$I$65,(PARAMETROS!$C$9-1)*15+1) | G13: =INDEX(CAP_CELULA!$J$6:$J$65,(PARAMETROS!$C$9-1)*15+1) | H13: =INDEX(CAP_CELULA!$K$6:$K$65,(PARAMETROS!$C$9-1)*15+1) | I13: =INDEX(CAP_CELULA!$Q$6:$Q$65,(PARAMETROS!$C$9-1)*15+1) | J13: =IF(B13="",0,IF(OR($C$4="TODAS",C13=$C$4),1,0)) | K13: =INDEX(CAP_CELULA!$O$6:$O$65,(PARAMETROS!$C$9-1)*15+1) | L13: =INDEX(CAP_CELULA!$F$6:$F$65,(PARAMETROS!$C$9-1)*15+1) | M13: =J13*G13+1/10000000
A14: 2 | B14: =INDEX(CAP_CELULA!$C$6:$C$65,(PARAMETROS!$C$9-1)*15+2) | C14: =INDEX(CAP_CELULA!$D$6:$D$65,(PARAMETROS!$C$9-1)*15+2) | D14: =INDEX(CAP_CELULA!$E$6:$E$65,(PARAMETROS!$C$9-1)*15+2) | E14: =INDEX(CAP_CELULA!$G$6:$G$65,(PARAMETROS!$C$9-1)*15+2) | F14: =INDEX(CAP_CELULA!$I$6:$I$65,(PARAMETROS!$C$9-1)*15+2) | G14: =INDEX(CAP_CELULA!$J$6:$J$65,(PARAMETROS!$C$9-1)*15+2) | H14: =INDEX(CAP_CELULA!$K$6:$K$65,(PARAMETROS!$C$9-1)*15+2) | I14: =INDEX(CAP_CELULA!$Q$6:$Q$65,(PARAMETROS!$C$9-1)*15+2) | J14: =IF(B14="",0,IF(OR($C$4="TODAS",C14=$C$4),1,0)) | K14: =INDEX(CAP_CELULA!$O$6:$O$65,(PARAMETROS!$C$9-1)*15+2) | L14: =INDEX(CAP_CELULA!$F$6:$F$65,(PARAMETROS!$C$9-1)*15+2) | M14: =J14*G14+2/10000000
A15: 3 | B15: =INDEX(CAP_CELULA!$C$6:$C$65,(PARAMETROS!$C$9-1)*15+3) | C15: =INDEX(CAP_CELULA!$D$6:$D$65,(PARAMETROS!$C$9-1)*15+3) | D15: =INDEX(CAP_CELULA!$E$6:$E$65,(PARAMETROS!$C$9-1)*15+3) | E15: =INDEX(CAP_CELULA!$G$6:$G$65,(PARAMETROS!$C$9-1)*15+3) | F15: =INDEX(CAP_CELULA!$I$6:$I$65,(PARAMETROS!$C$9-1)*15+3) | G15: =INDEX(CAP_CELULA!$J$6:$J$65,(PARAMETROS!$C$9-1)*15+3) | H15: =INDEX(CAP_CELULA!$K$6:$K$65,(PARAMETROS!$C$9-1)*15+3) | I15: =INDEX(CAP_CELULA!$Q$6:$Q$65,(PARAMETROS!$C$9-1)*15+3) | J15: =IF(B15="",0,IF(OR($C$4="TODAS",C15=$C$4),1,0)) | K15: =INDEX(CAP_CELULA!$O$6:$O$65,(PARAMETROS!$C$9-1)*15+3) | L15: =INDEX(CAP_CELULA!$F$6:$F$65,(PARAMETROS!$C$9-1)*15+3) | M15: =J15*G15+3/10000000
A16: 4 | B16: =INDEX(CAP_CELULA!$C$6:$C$65,(PARAMETROS!$C$9-1)*15+4) | C16: =INDEX(CAP_CELULA!$D$6:$D$65,(PARAMETROS!$C$9-1)*15+4) | D16: =INDEX(CAP_CELULA!$E$6:$E$65,(PARAMETROS!$C$9-1)*15+4) | E16: =INDEX(CAP_CELULA!$G$6:$G$65,(PARAMETROS!$C$9-1)*15+4) | F16: =INDEX(CAP_CELULA!$I$6:$I$65,(PARAMETROS!$C$9-1)*15+4) | G16: =INDEX(CAP_CELULA!$J$6:$J$65,(PARAMETROS!$C$9-1)*15+4) | H16: =INDEX(CAP_CELULA!$K$6:$K$65,(PARAMETROS!$C$9-1)*15+4) | I16: =INDEX(CAP_CELULA!$Q$6:$Q$65,(PARAMETROS!$C$9-1)*15+4) | J16: =IF(B16="",0,IF(OR($C$4="TODAS",C16=$C$4),1,0)) | K16: =INDEX(CAP_CELULA!$O$6:$O$65,(PARAMETROS!$C$9-1)*15+4) | L16: =INDEX(CAP_CELULA!$F$6:$F$65,(PARAMETROS!$C$9-1)*15+4) | M16: =J16*G16+4/10000000
A17: 5 | B17: =INDEX(CAP_CELULA!$C$6:$C$65,(PARAMETROS!$C$9-1)*15+5) | C17: =INDEX(CAP_CELULA!$D$6:$D$65,(PARAMETROS!$C$9-1)*15+5) | D17: =INDEX(CAP_CELULA!$E$6:$E$65,(PARAMETROS!$C$9-1)*15+5) | E17: =INDEX(CAP_CELULA!$G$6:$G$65,(PARAMETROS!$C$9-1)*15+5) | F17: =INDEX(CAP_CELULA!$I$6:$I$65,(PARAMETROS!$C$9-1)*15+5) | G17: =INDEX(CAP_CELULA!$J$6:$J$65,(PARAMETROS!$C$9-1)*15+5) | H17: =INDEX(CAP_CELULA!$K$6:$K$65,(PARAMETROS!$C$9-1)*15+5) | I17: =INDEX(CAP_CELULA!$Q$6:$Q$65,(PARAMETROS!$C$9-1)*15+5) | J17: =IF(B17="",0,IF(OR($C$4="TODAS",C17=$C$4),1,0)) | K17: =INDEX(CAP_CELULA!$O$6:$O$65,(PARAMETROS!$C$9-1)*15+5) | L17: =INDEX(CAP_CELULA!$F$6:$F$65,(PARAMETROS!$C$9-1)*15+5) | M17: =J17*G17+5/10000000
A18: 6 | B18: =INDEX(CAP_CELULA!$C$6:$C$65,(PARAMETROS!$C$9-1)*15+6) | C18: =INDEX(CAP_CELULA!$D$6:$D$65,(PARAMETROS!$C$9-1)*15+6) | D18: =INDEX(CAP_CELULA!$E$6:$E$65,(PARAMETROS!$C$9-1)*15+6) | E18: =INDEX(CAP_CELULA!$G$6:$G$65,(PARAMETROS!$C$9-1)*15+6) | F18: =INDEX(CAP_CELULA!$I$6:$I$65,(PARAMETROS!$C$9-1)*15+6) | G18: =INDEX(CAP_CELULA!$J$6:$J$65,(PARAMETROS!$C$9-1)*15+6) | H18: =INDEX(CAP_CELULA!$K$6:$K$65,(PARAMETROS!$C$9-1)*15+6) | I18: =INDEX(CAP_CELULA!$Q$6:$Q$65,(PARAMETROS!$C$9-1)*15+6) | J18: =IF(B18="",0,IF(OR($C$4="TODAS",C18=$C$4),1,0)) | K18: =INDEX(CAP_CELULA!$O$6:$O$65,(PARAMETROS!$C$9-1)*15+6) | L18: =INDEX(CAP_CELULA!$F$6:$F$65,(PARAMETROS!$C$9-1)*15+6) | M18: =J18*G18+6/10000000
A19: 7 | B19: =INDEX(CAP_CELULA!$C$6:$C$65,(PARAMETROS!$C$9-1)*15+7) | C19: =INDEX(CAP_CELULA!$D$6:$D$65,(PARAMETROS!$C$9-1)*15+7) | D19: =INDEX(CAP_CELULA!$E$6:$E$65,(PARAMETROS!$C$9-1)*15+7) | E19: =INDEX(CAP_CELULA!$G$6:$G$65,(PARAMETROS!$C$9-1)*15+7) | F19: =INDEX(CAP_CELULA!$I$6:$I$65,(PARAMETROS!$C$9-1)*15+7) | G19: =INDEX(CAP_CELULA!$J$6:$J$65,(PARAMETROS!$C$9-1)*15+7) | H19: =INDEX(CAP_CELULA!$K$6:$K$65,(PARAMETROS!$C$9-1)*15+7) | I19: =INDEX(CAP_CELULA!$Q$6:$Q$65,(PARAMETROS!$C$9-1)*15+7) | J19: =IF(B19="",0,IF(OR($C$4="TODAS",C19=$C$4),1,0)) | K19: =INDEX(CAP_CELULA!$O$6:$O$65,(PARAMETROS!$C$9-1)*15+7) | L19: =INDEX(CAP_CELULA!$F$6:$F$65,(PARAMETROS!$C$9-1)*15+7) | M19: =J19*G19+7/10000000
A20: 8 | B20: =INDEX(CAP_CELULA!$C$6:$C$65,(PARAMETROS!$C$9-1)*15+8) | C20: =INDEX(CAP_CELULA!$D$6:$D$65,(PARAMETROS!$C$9-1)*15+8) | D20: =INDEX(CAP_CELULA!$E$6:$E$65,(PARAMETROS!$C$9-1)*15+8) | E20: =INDEX(CAP_CELULA!$G$6:$G$65,(PARAMETROS!$C$9-1)*15+8) | F20: =INDEX(CAP_CELULA!$I$6:$I$65,(PARAMETROS!$C$9-1)*15+8) | G20: =INDEX(CAP_CELULA!$J$6:$J$65,(PARAMETROS!$C$9-1)*15+8) | H20: =INDEX(CAP_CELULA!$K$6:$K$65,(PARAMETROS!$C$9-1)*15+8) | I20: =INDEX(CAP_CELULA!$Q$6:$Q$65,(PARAMETROS!$C$9-1)*15+8) | J20: =IF(B20="",0,IF(OR($C$4="TODAS",C20=$C$4),1,0)) | K20: =INDEX(CAP_CELULA!$O$6:$O$65,(PARAMETROS!$C$9-1)*15+8) | L20: =INDEX(CAP_CELULA!$F$6:$F$65,(PARAMETROS!$C$9-1)*15+8) | M20: =J20*G20+8/10000000
A21: 9 | B21: =INDEX(CAP_CELULA!$C$6:$C$65,(PARAMETROS!$C$9-1)*15+9) | C21: =INDEX(CAP_CELULA!$D$6:$D$65,(PARAMETROS!$C$9-1)*15+9) | D21: =INDEX(CAP_CELULA!$E$6:$E$65,(PARAMETROS!$C$9-1)*15+9) | E21: =INDEX(CAP_CELULA!$G$6:$G$65,(PARAMETROS!$C$9-1)*15+9) | F21: =INDEX(CAP_CELULA!$I$6:$I$65,(PARAMETROS!$C$9-1)*15+9) | G21: =INDEX(CAP_CELULA!$J$6:$J$65,(PARAMETROS!$C$9-1)*15+9) | H21: =INDEX(CAP_CELULA!$K$6:$K$65,(PARAMETROS!$C$9-1)*15+9) | I21: =INDEX(CAP_CELULA!$Q$6:$Q$65,(PARAMETROS!$C$9-1)*15+9) | J21: =IF(B21="",0,IF(OR($C$4="TODAS",C21=$C$4),1,0)) | K21: =INDEX(CAP_CELULA!$O$6:$O$65,(PARAMETROS!$C$9-1)*15+9) | L21: =INDEX(CAP_CELULA!$F$6:$F$65,(PARAMETROS!$C$9-1)*15+9) | M21: =J21*G21+9/10000000
A22: 10 | B22: =INDEX(CAP_CELULA!$C$6:$C$65,(PARAMETROS!$C$9-1)*15+10) | C22: =INDEX(CAP_CELULA!$D$6:$D$65,(PARAMETROS!$C$9-1)*15+10) | D22: =INDEX(CAP_CELULA!$E$6:$E$65,(PARAMETROS!$C$9-1)*15+10) | E22: =INDEX(CAP_CELULA!$G$6:$G$65,(PARAMETROS!$C$9-1)*15+10) | F22: =INDEX(CAP_CELULA!$I$6:$I$65,(PARAMETROS!$C$9-1)*15+10) | G22: =INDEX(CAP_CELULA!$J$6:$J$65,(PARAMETROS!$C$9-1)*15+10) | H22: =INDEX(CAP_CELULA!$K$6:$K$65,(PARAMETROS!$C$9-1)*15+10) | I22: =INDEX(CAP_CELULA!$Q$6:$Q$65,(PARAMETROS!$C$9-1)*15+10) | J22: =IF(B22="",0,IF(OR($C$4="TODAS",C22=$C$4),1,0)) | K22: =INDEX(CAP_CELULA!$O$6:$O$65,(PARAMETROS!$C$9-1)*15+10) | L22: =INDEX(CAP_CELULA!$F$6:$F$65,(PARAMETROS!$C$9-1)*15+10) | M22: =J22*G22+10/10000000
A23: 11 | B23: =INDEX(CAP_CELULA!$C$6:$C$65,(PARAMETROS!$C$9-1)*15+11) | C23: =INDEX(CAP_CELULA!$D$6:$D$65,(PARAMETROS!$C$9-1)*15+11) | D23: =INDEX(CAP_CELULA!$E$6:$E$65,(PARAMETROS!$C$9-1)*15+11) | E23: =INDEX(CAP_CELULA!$G$6:$G$65,(PARAMETROS!$C$9-1)*15+11) | F23: =INDEX(CAP_CELULA!$I$6:$I$65,(PARAMETROS!$C$9-1)*15+11) | G23: =INDEX(CAP_CELULA!$J$6:$J$65,(PARAMETROS!$C$9-1)*15+11) | H23: =INDEX(CAP_CELULA!$K$6:$K$65,(PARAMETROS!$C$9-1)*15+11) | I23: =INDEX(CAP_CELULA!$Q$6:$Q$65,(PARAMETROS!$C$9-1)*15+11) | J23: =IF(B23="",0,IF(OR($C$4="TODAS",C23=$C$4),1,0)) | K23: =INDEX(CAP_CELULA!$O$6:$O$65,(PARAMETROS!$C$9-1)*15+11) | L23: =INDEX(CAP_CELULA!$F$6:$F$65,(PARAMETROS!$C$9-1)*15+11) | M23: =J23*G23+11/10000000
A24: 12 | B24: =INDEX(CAP_CELULA!$C$6:$C$65,(PARAMETROS!$C$9-1)*15+12) | C24: =INDEX(CAP_CELULA!$D$6:$D$65,(PARAMETROS!$C$9-1)*15+12) | D24: =INDEX(CAP_CELULA!$E$6:$E$65,(PARAMETROS!$C$9-1)*15+12) | E24: =INDEX(CAP_CELULA!$G$6:$G$65,(PARAMETROS!$C$9-1)*15+12) | F24: =INDEX(CAP_CELULA!$I$6:$I$65,(PARAMETROS!$C$9-1)*15+12) | G24: =INDEX(CAP_CELULA!$J$6:$J$65,(PARAMETROS!$C$9-1)*15+12) | H24: =INDEX(CAP_CELULA!$K$6:$K$65,(PARAMETROS!$C$9-1)*15+12) | I24: =INDEX(CAP_CELULA!$Q$6:$Q$65,(PARAMETROS!$C$9-1)*15+12) | J24: =IF(B24="",0,IF(OR($C$4="TODAS",C24=$C$4),1,0)) | K24: =INDEX(CAP_CELULA!$O$6:$O$65,(PARAMETROS!$C$9-1)*15+12) | L24: =INDEX(CAP_CELULA!$F$6:$F$65,(PARAMETROS!$C$9-1)*15+12) | M24: =J24*G24+12/10000000
A25: 13 | B25: =INDEX(CAP_CELULA!$C$6:$C$65,(PARAMETROS!$C$9-1)*15+13) | C25: =INDEX(CAP_CELULA!$D$6:$D$65,(PARAMETROS!$C$9-1)*15+13) | D25: =INDEX(CAP_CELULA!$E$6:$E$65,(PARAMETROS!$C$9-1)*15+13) | E25: =INDEX(CAP_CELULA!$G$6:$G$65,(PARAMETROS!$C$9-1)*15+13) | F25: =INDEX(CAP_CELULA!$I$6:$I$65,(PARAMETROS!$C$9-1)*15+13) | G25: =INDEX(CAP_CELULA!$J$6:$J$65,(PARAMETROS!$C$9-1)*15+13) | H25: =INDEX(CAP_CELULA!$K$6:$K$65,(PARAMETROS!$C$9-1)*15+13) | I25: =INDEX(CAP_CELULA!$Q$6:$Q$65,(PARAMETROS!$C$9-1)*15+13) | J25: =IF(B25="",0,IF(OR($C$4="TODAS",C25=$C$4),1,0)) | K25: =INDEX(CAP_CELULA!$O$6:$O$65,(PARAMETROS!$C$9-1)*15+13) | L25: =INDEX(CAP_CELULA!$F$6:$F$65,(PARAMETROS!$C$9-1)*15+13) | M25: =J25*G25+13/10000000
A26: 14 | B26: =INDEX(CAP_CELULA!$C$6:$C$65,(PARAMETROS!$C$9-1)*15+14) | C26: =INDEX(CAP_CELULA!$D$6:$D$65,(PARAMETROS!$C$9-1)*15+14) | D26: =INDEX(CAP_CELULA!$E$6:$E$65,(PARAMETROS!$C$9-1)*15+14) | E26: =INDEX(CAP_CELULA!$G$6:$G$65,(PARAMETROS!$C$9-1)*15+14) | F26: =INDEX(CAP_CELULA!$I$6:$I$65,(PARAMETROS!$C$9-1)*15+14) | G26: =INDEX(CAP_CELULA!$J$6:$J$65,(PARAMETROS!$C$9-1)*15+14) | H26: =INDEX(CAP_CELULA!$K$6:$K$65,(PARAMETROS!$C$9-1)*15+14) | I26: =INDEX(CAP_CELULA!$Q$6:$Q$65,(PARAMETROS!$C$9-1)*15+14) | J26: =IF(B26="",0,IF(OR($C$4="TODAS",C26=$C$4),1,0)) | K26: =INDEX(CAP_CELULA!$O$6:$O$65,(PARAMETROS!$C$9-1)*15+14) | L26: =INDEX(CAP_CELULA!$F$6:$F$65,(PARAMETROS!$C$9-1)*15+14) | M26: =J26*G26+14/10000000
A27: 15 | B27: =INDEX(CAP_CELULA!$C$6:$C$65,(PARAMETROS!$C$9-1)*15+15) | C27: =INDEX(CAP_CELULA!$D$6:$D$65,(PARAMETROS!$C$9-1)*15+15) | D27: =INDEX(CAP_CELULA!$E$6:$E$65,(PARAMETROS!$C$9-1)*15+15) | E27: =INDEX(CAP_CELULA!$G$6:$G$65,(PARAMETROS!$C$9-1)*15+15) | F27: =INDEX(CAP_CELULA!$I$6:$I$65,(PARAMETROS!$C$9-1)*15+15) | G27: =INDEX(CAP_CELULA!$J$6:$J$65,(PARAMETROS!$C$9-1)*15+15) | H27: =INDEX(CAP_CELULA!$K$6:$K$65,(PARAMETROS!$C$9-1)*15+15) | I27: =INDEX(CAP_CELULA!$Q$6:$Q$65,(PARAMETROS!$C$9-1)*15+15) | J27: =IF(B27="",0,IF(OR($C$4="TODAS",C27=$C$4),1,0)) | K27: =INDEX(CAP_CELULA!$O$6:$O$65,(PARAMETROS!$C$9-1)*15+15) | L27: =INDEX(CAP_CELULA!$F$6:$F$65,(PARAMETROS!$C$9-1)*15+15) | M27: =J27*G27+15/10000000
A29: UTILIZAÇÃO DAS MÁQUINAS DE USINAGEM
A30: # | B30: Máquina | D30: Turnos | E30: Capacidade (h) | F30: Carga (h) | G30: Utilização | H30: Saldo (h) | I30: Status
A31: 1 | B31: =INDEX(USINAGEM!$C$6:$C$29,(PARAMETROS!$C$9-1)*6+1) | D31: =INDEX(USINAGEM!$D$6:$D$29,(PARAMETROS!$C$9-1)*6+1) | E31: =INDEX(USINAGEM!$F$6:$F$29,(PARAMETROS!$C$9-1)*6+1) | F31: =INDEX(USINAGEM!$H$6:$H$29,(PARAMETROS!$C$9-1)*6+1) | G31: =INDEX(USINAGEM!$I$6:$I$29,(PARAMETROS!$C$9-1)*6+1) | H31: =INDEX(USINAGEM!$J$6:$J$29,(PARAMETROS!$C$9-1)*6+1) | I31: =INDEX(USINAGEM!$N$6:$N$29,(PARAMETROS!$C$9-1)*6+1)
A32: 2 | B32: =INDEX(USINAGEM!$C$6:$C$29,(PARAMETROS!$C$9-1)*6+2) | D32: =INDEX(USINAGEM!$D$6:$D$29,(PARAMETROS!$C$9-1)*6+2) | E32: =INDEX(USINAGEM!$F$6:$F$29,(PARAMETROS!$C$9-1)*6+2) | F32: =INDEX(USINAGEM!$H$6:$H$29,(PARAMETROS!$C$9-1)*6+2) | G32: =INDEX(USINAGEM!$I$6:$I$29,(PARAMETROS!$C$9-1)*6+2) | H32: =INDEX(USINAGEM!$J$6:$J$29,(PARAMETROS!$C$9-1)*6+2) | I32: =INDEX(USINAGEM!$N$6:$N$29,(PARAMETROS!$C$9-1)*6+2)
A33: 3 | B33: =INDEX(USINAGEM!$C$6:$C$29,(PARAMETROS!$C$9-1)*6+3) | D33: =INDEX(USINAGEM!$D$6:$D$29,(PARAMETROS!$C$9-1)*6+3) | E33: =INDEX(USINAGEM!$F$6:$F$29,(PARAMETROS!$C$9-1)*6+3) | F33: =INDEX(USINAGEM!$H$6:$H$29,(PARAMETROS!$C$9-1)*6+3) | G33: =INDEX(USINAGEM!$I$6:$I$29,(PARAMETROS!$C$9-1)*6+3) | H33: =INDEX(USINAGEM!$J$6:$J$29,(PARAMETROS!$C$9-1)*6+3) | I33: =INDEX(USINAGEM!$N$6:$N$29,(PARAMETROS!$C$9-1)*6+3)
A34: 4 | B34: =INDEX(USINAGEM!$C$6:$C$29,(PARAMETROS!$C$9-1)*6+4) | D34: =INDEX(USINAGEM!$D$6:$D$29,(PARAMETROS!$C$9-1)*6+4) | E34: =INDEX(USINAGEM!$F$6:$F$29,(PARAMETROS!$C$9-1)*6+4) | F34: =INDEX(USINAGEM!$H$6:$H$29,(PARAMETROS!$C$9-1)*6+4) | G34: =INDEX(USINAGEM!$I$6:$I$29,(PARAMETROS!$C$9-1)*6+4) | H34: =INDEX(USINAGEM!$J$6:$J$29,(PARAMETROS!$C$9-1)*6+4) | I34: =INDEX(USINAGEM!$N$6:$N$29,(PARAMETROS!$C$9-1)*6+4)
A35: 5 | B35: =INDEX(USINAGEM!$C$6:$C$29,(PARAMETROS!$C$9-1)*6+5) | D35: =INDEX(USINAGEM!$D$6:$D$29,(PARAMETROS!$C$9-1)*6+5) | E35: =INDEX(USINAGEM!$F$6:$F$29,(PARAMETROS!$C$9-1)*6+5) | F35: =INDEX(USINAGEM!$H$6:$H$29,(PARAMETROS!$C$9-1)*6+5) | G35: =INDEX(USINAGEM!$I$6:$I$29,(PARAMETROS!$C$9-1)*6+5) | H35: =INDEX(USINAGEM!$J$6:$J$29,(PARAMETROS!$C$9-1)*6+5) | I35: =INDEX(USINAGEM!$N$6:$N$29,(PARAMETROS!$C$9-1)*6+5)
A36: 6 | B36: =INDEX(USINAGEM!$C$6:$C$29,(PARAMETROS!$C$9-1)*6+6) | D36: =INDEX(USINAGEM!$D$6:$D$29,(PARAMETROS!$C$9-1)*6+6) | E36: =INDEX(USINAGEM!$F$6:$F$29,(PARAMETROS!$C$9-1)*6+6) | F36: =INDEX(USINAGEM!$H$6:$H$29,(PARAMETROS!$C$9-1)*6+6) | G36: =INDEX(USINAGEM!$I$6:$I$29,(PARAMETROS!$C$9-1)*6+6) | H36: =INDEX(USINAGEM!$J$6:$J$29,(PARAMETROS!$C$9-1)*6+6) | I36: =INDEX(USINAGEM!$N$6:$N$29,(PARAMETROS!$C$9-1)*6+6)
A38: CAPACIDADE POR FAMÍLIA
A39: # | B39: Família | E39: Capacidade (h) | F39: Carga (h) | G39: Utilização
A40: 1 | B40: =PARAMETROS!B40 | E40: =SUMPRODUCT(($C$13:$C$27=B40)*$E$13:$E$27) | F40: =SUMPRODUCT(($C$13:$C$27=B40)*$F$13:$F$27) | G40: =IF(E40>0,F40/E40,0)
A41: 2 | B41: =PARAMETROS!B41 | E41: =SUMPRODUCT(($C$13:$C$27=B41)*$E$13:$E$27) | F41: =SUMPRODUCT(($C$13:$C$27=B41)*$F$13:$F$27) | G41: =IF(E41>0,F41/E41,0)
A42: 3 | B42: =PARAMETROS!B42 | E42: =SUMPRODUCT(($C$13:$C$27=B42)*$E$13:$E$27) | F42: =SUMPRODUCT(($C$13:$C$27=B42)*$F$13:$F$27) | G42: =IF(E42>0,F42/E42,0)
A43: 4 | B43: =PARAMETROS!B43 | E43: =SUMPRODUCT(($C$13:$C$27=B43)*$E$13:$E$27) | F43: =SUMPRODUCT(($C$13:$C$27=B43)*$F$13:$F$27) | G43: =IF(E43>0,F43/E43,0)
A44: RANKING — CÉLULAS MAIS SOBRECARREGADAS (filtro aplicado)
A45: Pos. | B45: Célula | E45: Capacidade (h) | F45: Carga (h) | G45: Utilização
...

Sheet SIMULADOR
A1: SIMULADOR DE CAPACIDADE
A2: Altere as células amarelas. O cenário 'Simulação' recalcula tudo e é comparado ao Atual.
B4: ALAVANCAS
B5: Célula a alterar
B6: Variação de funcionários por turno ativo (+/-) | C6: 0
B7: Turno A ativo (1/0) | C7: 1 | D7: ← inicia igual ao cenário Atual
B8: Turno B ativo (1/0) | C8: 0 | D8: ← inicia igual ao cenário Atual
B9: Turno C ativo (1/0) | C9: 0 | D9: ← inicia igual ao cenário Atual
B10: Horas extras por turno/dia (h) | C10: 0 | D10: ← inicia igual ao cenário Atual
B11: Dias com HE no mês | C11: 0 | D11: ← inicia igual ao cenário Atual
B12: Eficiência operacional | C12: 0.845969 | D12: ← inicia igual ao cenário Atual
B13: Disponibilidade | C13: 0.955 | D13: ← inicia igual ao cenário Atual
B14: Fator de demanda (1,20 = +20%) | C14: 1 | D14: ← inicia igual ao cenário Atual
B15: Fator de tempo (0,90 = -10%) | C15: 0.9 | D15: ← inicia igual ao cenário Atual
B16: Base de tempo (Padrão/Real) | C16: Padrão | D16: ← inicia igual ao cenário Atual
B18: RESULTADO — CÉLULA SELECIONADA (Atual × Simulação)
B19: Indicador | C19: Atual | D19: Simulação | E19: Variação
B20: Funcionários | C20: =IFERROR(INDEX(CAP_CELULA!$E$6:$E$65,0+MATCH($C$5,MAO_OBRA!$A$6:$A$20,0)),0) | D20: =IFERROR(INDEX(CAP_CELULA!$E$6:$E$65,45+MATCH($C$5,MAO_OBRA!$A$6:$A$20,0)),0) | E20: =D20-C20
B21: Capacidade efetiva (h/mês) | C21: =IFERROR(INDEX(CAP_CELULA!$G$6:$G$65,0+MATCH($C$5,MAO_OBRA!$A$6:$A$20,0)),0) | D21: =IFERROR(INDEX(CAP_CELULA!$G$6:$G$65,45+MATCH($C$5,MAO_OBRA!$A$6:$A$20,0)),0) | E21: =D21-C21
B22: Carga (h/mês) | C22: =IFERROR(INDEX(CAP_CELULA!$I$6:$I$65,0+MATCH($C$5,MAO_OBRA!$A$6:$A$20,0)),0) | D22: =IFERROR(INDEX(CAP_CELULA!$I$6:$I$65,45+MATCH($C$5,MAO_OBRA!$A$6:$A$20,0)),0) | E22: =D22-C22
B23: Utilização | C23: =IFERROR(INDEX(CAP_CELULA!$J$6:$J$65,0+MATCH($C$5,MAO_OBRA!$A$6:$A$20,0)),0) | D23: =IFERROR(INDEX(CAP_CELULA!$J$6:$J$65,45+MATCH($C$5,MAO_OBRA!$A$6:$A$20,0)),0) | E23: =D23-C23
B24: Saldo (h) | C24: =IFERROR(INDEX(CAP_CELULA!$K$6:$K$65,0+MATCH($C$5,MAO_OBRA!$A$6:$A$20,0)),0) | D24: =IFERROR(INDEX(CAP_CELULA!$K$6:$K$65,45+MATCH($C$5,MAO_OBRA!$A$6:$A$20,0)),0) | E24: =D24-C24
B25: Capacidade equivalente (pç/mês) | C25: =IFERROR(INDEX(CAP_CELULA!$U$6:$U$65,0+MATCH($C$5,MAO_OBRA!$A$6:$A$20,0)),0) | D25: =IFERROR(INDEX(CAP_CELULA!$U$6:$U$65,45+MATCH($C$5,MAO_OBRA!$A$6:$A$20,0)),0) | E25: =D25-C25
B26: Extra com horas extras (h) | C26: =IFERROR(INDEX(CAP_CELULA!$H$6:$H$65,0+MATCH($C$5,MAO_OBRA!$A$6:$A$20,0)),0) | D26: =IFERROR(INDEX(CAP_CELULA!$H$6:$H$65,45+MATCH($C$5,MAO_OBRA!$A$6:$A$20,0)),0) | E26: =D26-C26
B28: RESULTADO GERAL (Simulação)
B29: Utilização geral da Caldeiraria | C29: =COMPARATIVO!F8
B30: Horas extras necessárias (h) | C30: =COMPARATIVO!F11
B31: Funcionários necessários para o plano | C31: =COMPARATIVO!F13
B32: Funcionários disponíveis | C32: =COMPARATIVO!F5
B33: Células INSUFICIENTES | C33: =COMPARATIVO!F15
B34: Máquinas INSUFICIENTES | C34: =COMPARATIVO!F17
B36: RESPOSTAS RÁPIDAS (Simulação)
B37: Célula mais sobrecarregada | C37: =IF(MAX(CAP_CELULA!$J$51:$J$65)=0,"-",INDEX(CAP_CELULA!$C$51:$C$65,MATCH(MAX(CAP_CELULA!$J$51:$J$65),CAP_CELULA!$J$51:$J$65,0)))
B38: utilização | C38: =MAX(CAP_CELULA!$J$51:$J$65)
B39: Célula com mais mão de obra ociosa | C39: =IF(MAX(CAP_CELULA!$L$51:$L$65)=0,"-",INDEX(CAP_CELULA!$C$51:$C$65,MATCH(MAX(CAP_CELULA!$L$51:$L$65),CAP_CELULA!$L$51:$L$65,0)))
B40: Máquina de usinagem limitante | C40: =IF(MAX(USINAGEM!$I$24:$I$29)=0,"-",INDEX(USINAGEM!$C$24:$C$29,MATCH(MAX(USINAGEM!$I$24:$I$29),USINAGEM!$I$24:$I$29,0)))
B41: utilização | C41: =MAX(USINAGEM!$I$24:$I$29)
B42: Linha (peça/processo) com maior consumo de horas | C42: =IFERROR(INDEX(DEMANDA_CARGA!$C$6:$C$205,MATCH(LARGE(DEMANDA_CARGA!$L$6:$L$205,1),DEMANDA_CARGA!$L$6:$L$205,0))&" / "&INDEX(DEMANDA_CARGA!$D$6:$D$205,MATCH(LARGE(DEMANDA_CARGA!$L$6:$L$205,1),DEMANDA_CARGA!$L$6:$L$205,0)),"-")
B44: Obs.: aba SIMULADOR usa o cenário 4 (Simulação). O Dashboard permite escolher qualquer cenário.

Sheet CAP_CELULA
A1: CAPACIDADE POR CÉLULA — 4 cenários (horas-homem/mês)
A2: Células são recursos independentes. Dentro de um fluxo, o limitante é a célula/máquina de maior utilização (ver DEMANDA_CARGA, coluna Gargalo).
A5: Cen. | B5: # | C5: Célula | D5: Família | E5: Funcionários | F5: Cap. nominal (h) | G5: Cap. efetiva (h) | H5: Cap. extra HE (h) | I5: Carga (h) | J5: Utilização | K5: Saldo (h) | L5: Ociosidade (h) | M5: Déficit (h) | N5: HE necessária (h) | O5: Func. adicionais | P5: Sogyodo | Q5: Status | R5: Util. c/ HE | S5: Cap. diária (h) | T5: Cap. semanal (h) | U5: Cap. equiv. (pç/mês)
A6: 1 | B6: 1 | C6: =IF(MAO_OBRA!A6="","",MAO_OBRA!A6) | D6: =IF(MAO_OBRA!B6="","",MAO_OBRA!B6) | E6: =MAO_OBRA!O6 | F6: =PARAMETROS!$C$4*(MAO_OBRA!C6*PARAMETROS!$C$18*PARAMETROS!$F$11+MAO_OBRA!D6*PARAMETROS!$C$19*PARAMETROS!$F$12+MAO_OBRA!E6*PARAMETROS!$C$20*PARAMETROS!$F$13) | G6: =F6*PARAMETROS!$C$23*PARAMETROS!$C$24 | H6: =PARAMETROS!$C$22*PARAMETROS!$C$21*E6*PARAMETROS!$C$23*PARAMETROS!$C$24 | I6: =IF(C6="",0,PARAMETROS!$C$25/60*(IF(PARAMETROS!$C$27="Real",SUMPRODUCT((BASE!$E$6:$E$205=C6)*BASE!$P$6:$P$205*BASE!$L$6:$L$205*BASE!$N$6:$N$205),SUMPRODUCT((BASE!$E$6:$E$205=C6)*BASE!$P$6:$P$205*BASE!$L$6:$L$205*BASE!$H$6:$H$205))*PARAMETROS!$C$26+SUMPRODUCT((BASE!$E$6:$E$205=C6)*BASE!$P$6:$P$205*BASE!$L$6:$L$205*BASE!$O$6:$O$205))) | J6: =IF(G6>0,I6/G6,0) | K6: =G6-I6 | L6: =MAX(0,K6) | M6: =MAX(0,-K6) | N6: =M6 | O6: =IF(PARAMETROS!$C$28>0,M6/PARAMETROS!$C$28,0) | P6: =IF(PARAMETROS!$C$8="Nominal",IF(F6>0,I6/F6,0),J6) | Q6: =IF(C6="","",IF(I6=0,"SEM CARGA",IF(OR(G6=0,J6>=PARAMETROS!$C$7),"INSUFICIENTE",IF(J6>=PARAMETROS!$C$6,"ATENÇÃO","OK")))) | R6: =IF(G6+H6>0,I6/(G6+H6),0) | S6: =G6/PARAMETROS!$C$4 | T6: =S6*PARAMETROS!$C$5 | U6: =IF(I6>0,SUMIF(BASE!$E$6:$E$205,C6,BASE!$L$6:$L$205)*PARAMETROS!$C$25*G6/I6,0)
A7: 1 | B7: 2 | C7: =IF(MAO_OBRA!A7="","",MAO_OBRA!A7) | D7: =IF(MAO_OBRA!B7="","",MAO_OBRA!B7) | E7: =MAO_OBRA!O7 | F7: =PARAMETROS!$C$4*(MAO_OBRA!C7*PARAMETROS!$C$18*PARAMETROS!$F$11+MAO_OBRA!D7*PARAMETROS!$C$19*PARAMETROS!$F$12+MAO_OBRA!E7*PARAMETROS!$C$20*PARAMETROS!$F$13) | G7: =F7*PARAMETROS!$C$23*PARAMETROS!$C$24 | H7: =PARAMETROS!$C$22*PARAMETROS!$C$21*E7*PARAMETROS!$C$23*PARAMETROS!$C$24 | I7: =IF(C7="",0,PARAMETROS!$C$25/60*(IF(PARAMETROS!$C$27="Real",SUMPRODUCT((BASE!$E$6:$E$205=C7)*BASE!$P$6:$P$205*BASE!$L$6:$L$205*BASE!$N$6:$N$205),SUMPRODUCT((BASE!$E$6:$E$205=C7)*BASE!$P$6:$P$205*BASE!$L$6:$L$205*BASE!$H$6:$H$205))*PARAMETROS!$C$26+SUMPRODUCT((BASE!$E$6:$E$205=C7)*BASE!$P$6:$P$205*BASE!$L$6:$L$205*BASE!$O$6:$O$205))) | J7: =IF(G7>0,I7/G7,0) | K7: =G7-I7 | L7: =MAX(0,K7) | M7: =MAX(0,-K7) | N7: =M7 | O7: =IF(PARAMETROS!$C$28>0,M7/PARAMETROS!$C$28,0) | P7: =IF(PARAMETROS!$C$8="Nominal",IF(F7>0,I7/F7,0),J7) | Q7: =IF(C7="","",IF(I7=0,"SEM CARGA",IF(OR(G7=0,J7>=PARAMETROS!$C$7),"INSUFICIENTE",IF(J7>=PARAMETROS!$C$6,"ATENÇÃO","OK")))) | R7: =IF(G7+H7>0,I7/(G7+H7),0) | S7: =G7/PARAMETROS!$C$4 | T7: =S7*PARAMETROS!$C$5 | U7: =IF(I7>0,SUMIF(BASE!$E$6:$E$205,C7,BASE!$L$6:$L$205)*PARAMETROS!$C$25*G7/I7,0)
A8: 1 | B8: 3 | C8: =IF(MAO_OBRA!A8="","",MAO_OBRA!A8) | D8: =IF(MAO_OBRA!B8="","",MAO_OBRA!B8) | E8: =MAO_OBRA!O8 | F8: =PARAMETROS!$C$4*(MAO_OBRA!C8*PARAMETROS!$C$18*PARAMETROS!$F$11+MAO_OBRA!D8*PARAMETROS!$C$19*PARAMETROS!$F$12+MAO_OBRA!E8*PARAMETROS!$C$20*PARAMETROS!$F$13) | G8: =F8*PARAMETROS!$C$23*PARAMETROS!$C$24 | H8: =PARAMETROS!$C$22*PARAMETROS!$C$21*E8*PARAMETROS!$C$23*PARAMETROS!$C$24 | I8: =IF(C8="",0,PARAMETROS!$C$25/60*(IF(PARAMETROS!$C$27="Real",SUMPRODUCT((BASE!$E$6:$E$205=C8)*BASE!$P$6:$P$205*BASE!$L$6:$L$205*BASE!$N$6:$N$205),SUMPRODUCT((BASE!$E$6:$E$205=C8)*BASE!$P$6:$P$205*BASE!$L$6:$L$205*BASE!$H$6:$H$205))*PARAMETROS!$C$26+SUMPRODUCT((BASE!$E$6:$E$205=C8)*BASE!$P$6:$P$205*BASE!$L$6:$L$205*BASE!$O$6:$O$205))) | J8: =IF(G8>0,I8/G8,0) | K8: =G8-I8 | L8: =MAX(0,K8) | M8: =MAX(0,-K8) | N8: =M8 | O8: =IF(PARAMETROS!$C$28>0,M8/PARAMETROS!$C$28,0) | P8: =IF(PARAMETROS!$C$8="Nominal",IF(F8>0,I8/F8,0),J8) | Q8: =IF(C8="","",IF(I8=0,"SEM CARGA",IF(OR(G8=0,J8>=PARAMETROS!$C$7),"INSUFICIENTE",IF(J8>=PARAMETROS!$C$6,"ATENÇÃO","OK")))) | R8: =IF(G8+H8>0,I8/(G8+H8),0) | S8: =G8/PARAMETROS!$C$4 | T8: =S8*PARAMETROS!$C$5 | U8: =IF(I8>0,SUMIF(BASE!$E$6:$E$205,C8,BASE!$L$6:$L$205)*PARAMETROS!$C$25*G8/I8,0)
A9: 1 | B9: 4 | C9: =IF(MAO_OBRA!A9="","",MAO_OBRA!A9) | D9: =IF(MAO_OBRA!B9="","",MAO_OBRA!B9) | E9: =MAO_OBRA!O9 | F9: =PARAMETROS!$C$4*(MAO_OBRA!C9*PARAMETROS!$C$18*PARAMETROS!$F$11+MAO_OBRA!D9*PARAMETROS!$C$19*PARAMETROS!$F$12+MAO_OBRA!E9*PARAMETROS!$C$20*PARAMETROS!$F$13) | G9: =F9*PARAMETROS!$C$23*PARAMETROS!$C$24 | H9: =PARAMETROS!$C$22*PARAMETROS!$C$21*E9*PARAMETROS!$C$23*PARAMETROS!$C$24 | I9: =IF(C9="",0,PARAMETROS!$C$25/60*(IF(PARAMETROS!$C$27="Real",SUMPRODUCT((BASE!$E$6:$E$205=C9)*BASE!$P$6:$P$205*BASE!$L$6:$L$205*BASE!$N$6:$N$205),SUMPRODUCT((BASE!$E$6:$E$205=C9)*BASE!$P$6:$P$205*BASE!$L$6:$L$205*BASE!$H$6:$H$205))*PARAMETROS!$C$26+SUMPRODUCT((BASE!$E$6:$E$205=C9)*BASE!$P$6:$P$205*BASE!$L$6:$L$205*BASE!$O$6:$O$205))) | J9: =IF(G9>0,I9/G9,0) | K9: =G9-I9 | L9: =MAX(0,K9) | M9: =MAX(0,-K9) | N9: =M9 | O9: =IF(PARAMETROS!$C$28>0,M9/PARAMETROS!$C$28,0) | P9: =IF(PARAMETROS!$C$8="Nominal",IF(F9>0,I9/F9,0),J9) | Q9: =IF(C9="","",IF(I9=0,"SEM CARGA",IF(OR(G9=0,J9>=PARAMETROS!$C$7),"INSUFICIENTE",IF(J9>=PARAMETROS!$C$6,"ATENÇÃO","OK")))) | R9: =IF(G9+H9>0,I9/(G9+H9),0) | S9: =G9/PARAMETROS!$C$4 | T9: =S9*PARAMETROS!$C$5 | U9: =IF(I9>0,SUMIF(BASE!$E$6:$E$205,C9,BASE!$L$6:$L$205)*PARAMETROS!$C$25*G9/I9,0)
A10: 1 | B10: 5 | C10: =IF(MAO_OBRA!A10="","",MAO_OBRA!A10) | D10: =IF(MAO_OBRA!B10="","",MAO_OBRA!B10) | E10: =MAO_OBRA!O10 | F10: =PARAMETROS!$C$4*(MAO_OBRA!C10*PARAMETROS!$C$18*PARAMETROS!$F$11+MAO_OBRA!D10*PARAMETROS!$C$19*PARAMETROS!$F$12+MAO_OBRA!E10*PARAMETROS!$C$20*PARAMETROS!$F$13) | G10: =F10*PARAMETROS!$C$23*PARAMETROS!$C$24 | H10: =PARAMETROS!$C$22*PARAMETROS!$C$21*E10*PARAMETROS!$C$23*PARAMETROS!$C$24 | I10: =IF(C10="",0,PARAMETROS!$C$25/60*(IF(PARAMETROS!$C$27="Real",SUMPRODUCT((BASE!$E$6:$E$205=C10)*BASE!$P$6:$P$205*BASE!$L$6:$L$205*BASE!$N$6:$N$205),SUMPRODUCT((BASE!$E$6:$E$205=C10)*BASE!$P$6:$P$205*BASE!$L$6:$L$205*BASE!$H$6:$H$205))*PARAMETROS!$C$26+SUMPRODUCT((BASE!$E$6:$E$205=C10)*BASE!$P$6:$P$205*BASE!$L$6:$L$205*BASE!$O$6:$O$205))) | J10: =IF(G10>0,I10/G10,0) | K10: =G10-I10 | L10: =MAX(0,K10) | M10: =MAX(0,-K10) | N10: =M10 | O10: =IF(PARAMETROS!$C$28>0,M10/PARAMETROS!$C$28,0) | P10: =IF(PARAMETROS!$C$8="Nominal",IF(F10>0,I10/F10,0),J10) | Q10: =IF(C10="","",IF(I10=0,"SEM CARGA",IF(OR(G10=0,J10>=PARAMETROS!$C$7),"INSUFICIENTE",IF(J10>=PARAMETROS!$C$6,"ATENÇÃO","OK")))) | R10: =IF(G10+H10>0,I10/(G10+H10),0) | S10: =G10/PARAMETROS!$C$4 | T10: =S10*PARAMETROS!$C$5 | U10: =IF(I10>0,SUMIF(BASE!$E$6:$E$205,C10,BASE!$L$6:$L$205)*PARAMETROS!$C$25*G10/I10,0)
A11: 1 | B11: 6 | C11: =IF(MAO_OBRA!A11="","",MAO_OBRA!A11) | D11: =IF(MAO_OBRA!B11="","",MAO_OBRA!B11) | E11: =MAO_OBRA!O11 | F11: =PARAMETROS!$C$4*(MAO_OBRA!C11*PARAMETROS!$C$18*PARAMETROS!$F$11+MAO_OBRA!D11*PARAMETROS!$C$19*PARAMETROS!$F$12+MAO_OBRA!E11*PARAMETROS!$C$20*PARAMETROS!$F$13) | G11: =F11*PARAMETROS!$C$23*PARAMETROS!$C$24 | H11: =PARAMETROS!$C$22*PARAMETROS!$C$21*E11*PARAMETROS!$C$23*PARAMETROS!$C$24 | I11: =IF(C11="",0,PARAMETROS!$C$25/60*(IF(PARAMETROS!$C$27="Real",SUMPRODUCT((BASE!$E$6:$E$205=C11)*BASE!$P$6:$P$205*BASE!$L$6:$L$205*BASE!$N$6:$N$205),SUMPRODUCT((BASE!$E$6:$E$205=C11)*BASE!$P$6:$P$205*BASE!$L$6:$L$205*BASE!$H$6:$H$205))*PARAMETROS!$C$26+SUMPRODUCT((BASE!$E$6:$E$205=C11)*BASE!$P$6:$P$205*BASE!$L$6:$L$205*BASE!$O$6:$O$205))) | J11: =IF(G11>0,I11/G11,0) | K11: =G11-I11 | L11: =MAX(0,K11) | M11: =MAX(0,-K11) | N11: =M11 | O11: =IF(PARAMETROS!$C$28>0,M11/PARAMETROS!$C$28,0) | P11: =IF(PARAMETROS!$C$8="Nominal",IF(F11>0,I11/F11,0),J11) | Q11: =IF(C11="","",IF(I11=0,"SEM CARGA",IF(OR(G11=0,J11>=PARAMETROS!$C$7),"INSUFICIENTE",IF(J11>=PARAMETROS!$C$6,"ATENÇÃO","OK")))) | R11: =IF(G11+H11>0,I11/(G11+H11),0) | S11: =G11/PARAMETROS!$C$4 | T11: =S11*PARAMETROS!$C$5 | U11: =IF(I11>0,SUMIF(BASE!$E$6:$E$205,C11,BASE!$L$6:$L$205)*PARAMETROS!$C$25*G11/I11,0)
A12: 1 | B12: 7 | C12: =IF(MAO_OBRA!A12="","",MAO_OBRA!A12) | D12: =IF(MAO_OBRA!B12="","",MAO_OBRA!B12) | E12: =MAO_OBRA!O12 | F12: =PARAMETROS!$C$4*(MAO_OBRA!C12*PARAMETROS!$C$18*PARAMETROS!$F$11+MAO_OBRA!D12*PARAMETROS!$C$19*PARAMETROS!$F$12+MAO_OBRA!E12*PARAMETROS!$C$20*PARAMETROS!$F$13) | G12: =F12*PARAMETROS!$C$23*PARAMETROS!$C$24 | H12: =PARAMETROS!$C$22*PARAMETROS!$C$21*E12*PARAMETROS!$C$23*PARAMETROS!$C$24 | I12: =IF(C12="",0,PARAMETROS!$C$25/60*(IF(PARAMETROS!$C$27="Real",SUMPRODUCT((BASE!$E$6:$E$205=C12)*BASE!$P$6:$P$205*BASE!$L$6:$L$205*BASE!$N$6:$N$205),SUMPRODUCT((BASE!$E$6:$E$205=C12)*BASE!$P$6:$P$205*BASE!$L$6:$L$205*BASE!$H$6:$H$205))*PARAMETROS!$C$26+SUMPRODUCT((BASE!$E$6:$E$205=C12)*BASE!$P$6:$P$205*BASE!$L$6:$L$205*BASE!$O$6:$O$205))) | J12: =IF(G12>0,I12/G12,0) | K12: =G12-I12 | L12: =MAX(0,K12) | M12: =MAX(0,-K12) | N12: =M12 | O12: =IF(PARAMETROS!$C$28>0,M12/PARAMETROS!$C$28,0) | P12: =IF(PARAMETROS!$C$8="Nominal",IF(F12>0,I12/F12,0),J12) | Q12: =IF(C12="","",IF(I12=0,"SEM CARGA",IF(OR(G12=0,J12>=PARAMETROS!$C$7),"INSUFICIENTE",IF(J12>=PARAMETROS!$C$6,"ATENÇÃO","OK")))) | R12: =IF(G12+H12>0,I12/(G12+H12),0) | S12: =G12/PARAMETROS!$C$4 | T12: =S12*PARAMETROS!$C$5 | U12: =IF(I12>0,SUMIF(BASE!$E$6:$E$205,C12,BASE!$L$6:$L$205)*PARAMETROS!$C$25*G12/I12,0)
A13: 1 | B13: 8 | C13: =IF(MAO_OBRA!A13="","",MAO_OBRA!A13) | D13: =IF(MAO_OBRA!B13="","",MAO_OBRA!B13) | E13: =MAO_OBRA!O13 | F13: =PARAMETROS!$C$4*(MAO_OBRA!C13*PARAMETROS!$C$18*PARAMETROS!$F$11+MAO_OBRA!D13*PARAMETROS!$C$19*PARAMETROS!$F$12+MAO_OBRA!E13*PARAMETROS!$C$20*PARAMETROS!$F$13) | G13: =F13*PARAMETROS!$C$23*PARAMETROS!$C$24 | H13: =PARAMETROS!$C$22*PARAMETROS!$C$21*E13*PARAMETROS!$C$23*PARAMETROS!$C$24 | I13: =IF(C13="",0,PARAMETROS!$C$25/60*(IF(PARAMETROS!$C$27="Real",SUMPRODUCT((BASE!$E$6:$E$205=C13)*BASE!$P$6:$P$205*BASE!$L$6:$L$205*BASE!$N$6:$N$205),SUMPRODUCT((BASE!$E$6:$E$205=C13)*BASE!$P$6:$P$205*BASE!$L$6:$L$205*BASE!$H$6:$H$205))*PARAMETROS!$C$26+SUMPRODUCT((BASE!$E$6:$E$205=C13)*BASE!$P$6:$P$205*BASE!$L$6:$L$205*BASE!$O$6:$O$205))) | J13: =IF(G13>0,I13/G13,0) | K13: =G13-I13 | L13: =MAX(0,K13) | M13: =MAX(0,-K13) | N13: =M13 | O13: =IF(PARAMETROS!$C$28>0,M13/PARAMETROS!$C$28,0) | P13: =IF(PARAMETROS!$C$8="Nominal",IF(F13>0,I13/F13,0),J13) | Q13: =IF(C13="","",IF(I13=0,"SEM CARGA",IF(OR(G13=0,J13>=PARAMETROS!$C$7),"INSUFICIENTE",IF(J13>=PARAMETROS!$C$6,"ATENÇÃO","OK")))) | R13: =IF(G13+H13>0,I13/(G13+H13),0) | S13: =G13/PARAMETROS!$C$4 | T13: =S13*PARAMETROS!$C$5 | U13: =IF(I13>0,SUMIF(BASE!$E$6:$E$205,C13,BASE!$L$6:$L$205)*PARAMETROS!$C$25*G13/I13,0)
A14: 1 | B14: 9 | C14: =IF(MAO_OBRA!A14="","",MAO_OBRA!A14) | D14: =IF(MAO_OBRA!B14="","",MAO_OBRA!B14) | E14: =MAO_OBRA!O14 | F14: =PARAMETROS!$C$4*(MAO_OBRA!C14*PARAMETROS!$C$18*PARAMETROS!$F$11+MAO_OBRA!D14*PARAMETROS!$C$19*PARAMETROS!$F$12+MAO_OBRA!E14*PARAMETROS!$C$20*PARAMETROS!$F$13) | G14: =F14*PARAMETROS!$C$23*PARAMETROS!$C$24 | H14: =PARAMETROS!$C$22*PARAMETROS!$C$21*E14*PARAMETROS!$C$23*PARAMETROS!$C$24 | I14: =IF(C14="",0,PARAMETROS!$C$25/60*(IF(PARAMETROS!$C$27="Real",SUMPRODUCT((BASE!$E$6:$E$205=C14)*BASE!$P$6:$P$205*BASE!$L$6:$L$205*BASE!$N$6:$N$205),SUMPRODUCT((BASE!$E$6:$E$205=C14)*BASE!$P$6:$P$205*BASE!$L$6:$L$205*BASE!$H$6:$H$205))*PARAMETROS!$C$26+SUMPRODUCT((BASE!$E$6:$E$205=C14)*BASE!$P$6:$P$205*BASE!$L$6:$L$205*BASE!$O$6:$O$205))) | J14: =IF(G14>0,I14/G14,0) | K14: =G14-I14 | L14: =MAX(0,K14) | M14: =MAX(0,-K14) | N14: =M14 | O14: =IF(PARAMETROS!$C$28>0,M14/PARAMETROS!$C$28,0) | P14: =IF(PARAMETROS!$C$8="Nominal",IF(F14>0,I14/F14,0),J14) | Q14: =IF(C14="","",IF(I14=0,"SEM CARGA",IF(OR(G14=0,J14>=PARAMETROS!$C$7),"INSUFICIENTE",IF(J14>=PARAMETROS!$C$6,"ATENÇÃO","OK")))) | R14: =IF(G14+H14>0,I14/(G14+H14),0) | S14: =G14/PARAMETROS!$C$4 | T14: =S14*PARAMETROS!$C$5 | U14: =IF(I14>0,SUMIF(BASE!$E$6:$E$205,C14,BASE!$L$6:$L$205)*PARAMETROS!$C$25*G14/I14,0)
A15: 1 | B15: 10 | C15: =IF(MAO_OBRA!A15="","",MAO_OBRA!A15) | D15: =IF(MAO_OBRA!B15="","",MAO_OBRA!B15) | E15: =MAO_OBRA!O15 | F15: =PARAMETROS!$C$4*(MAO_OBRA!C15*PARAMETROS!$C$18*PARAMETROS!$F$11+MAO_OBRA!D15*PARAMETROS!$C$19*PARAMETROS!$F$12+MAO_OBRA!E15*PARAMETROS!$C$20*PARAMETROS!$F$13) | G15: =F15*PARAMETROS!$C$23*PARAMETROS!$C$24 | H15: =PARAMETROS!$C$22*PARAMETROS!$C$21*E15*PARAMETROS!$C$23*PARAMETROS!$C$24 | I15: =IF(C15="",0,PARAMETROS!$C$25/60*(IF(PARAMETROS!$C$27="Real",SUMPRODUCT((BASE!$E$6:$E$205=C15)*BASE!$P$6:$P$205*BASE!$L$6:$L$205*BASE!$N$6:$N$205),SUMPRODUCT((BASE!$E$6:$E$205=C15)*BASE!$P$6:$P$205*BASE!$L$6:$L$205*BASE!$H$6:$H$205))*PARAMETROS!$C$26+SUMPRODUCT((BASE!$E$6:$E$205=C15)*BASE!$P$6:$P$205*BASE!$L$6:$L$205*BASE!$O$6:$O$205))) | J15: =IF(G15>0,I15/G15,0) | K15: =G15-I15 | L15: =MAX(0,K15) | M15: =MAX(0,-K15) | N15: =M15 | O15: =IF(PARAMETROS!$C$28>0,M15/PARAMETROS!$C$28,0) | P15: =IF(PARAMETROS!$C$8="Nominal",IF(F15>0,I15/F15,0),J15) | Q15: =IF(C15="","",IF(I15=0,"SEM CARGA",IF(OR(G15=0,J15>=PARAMETROS!$C$7),"INSUFICIENTE",IF(J15>=PARAMETROS!$C$6,"ATENÇÃO","OK")))) | R15: =IF(G15+H15>0,I15/(G15+H15),0) | S15: =G15/PARAMETROS!$C$4 | T15: =S15*PARAMETROS!$C$5 | U15: =IF(I15>0,SUMIF(BASE!$E$6:$E$205,C15,BASE!$L$6:$L$205)*PARAMETROS!$C$25*G15/I15,0)
A16: 1 | B16: 11 | C16: =IF(MAO_OBRA!A16="","",MAO_OBRA!A16) | D16: =IF(MAO_OBRA!B16="","",MAO_OBRA!B16) | E16: =MAO_OBRA!O16 | F16: =PARAMETROS!$C$4*(MAO_OBRA!C16*PARAMETROS!$C$18*PARAMETROS!$F$11+MAO_OBRA!D16*PARAMETROS!$C$19*PARAMETROS!$F$12+MAO_OBRA!E16*PARAMETROS!$C$20*PARAMETROS!$F$13) | G16: =F16*PARAMETROS!$C$23*PARAMETROS!$C$24 | H16: =PARAMETROS!$C$22*PARAMETROS!$C$21*E16*PARAMETROS!$C$23*PARAMETROS!$C$24 | I16: =IF(C16="",0,PARAMETROS!$C$25/60*(IF(PARAMETROS!$C$27="Real",SUMPRODUCT((BASE!$E$6:$E$205=C16)*BASE!$P$6:$P$205*BASE!$L$6:$L$205*BASE!$N$6:$N$205),SUMPRODUCT((BASE!$E$6:$E$205=C16)*BASE!$P$6:$P$205*BASE!$L$6:$L$205*BASE!$H$6:$H$205))*PARAMETROS!$C$26+SUMPRODUCT((BASE!$E$6:$E$205=C16)*BASE!$P$6:$P$205*BASE!$L$6:$L$205*BASE!$O$6:$O$205))) | J16: =IF(G16>0,I16/G16,0) | K16: =G16-I16 | L16: =MAX(0,K16) | M16: =MAX(0,-K16) | N16: =M16 | O16: =IF(PARAMETROS!$C$28>0,M16/PARAMETROS!$C$28,0) | P16: =IF(PARAMETROS!$C$8="Nominal",IF(F16>0,I16/F16,0),J16) | Q16: =IF(C16="","",IF(I16=0,"SEM CARGA",IF(OR(G16=0,J16>=PARAMETROS!$C$7),"INSUFICIENTE",IF(J16>=PARAMETROS!$C$6,"ATENÇÃO","OK")))) | R16: =IF(G16+H16>0,I16/(G16+H16),0) | S16: =G16/PARAMETROS!$C$4 | T16: =S16*PARAMETROS!$C$5 | U16: =IF(I16>0,SUMIF(BASE!$E$6:$E$205,C16,BASE!$L$6:$L$205)*PARAMETROS!$C$25*G16/I16,0)
A17: 1 | B17: 12 | C17: =IF(MAO_OBRA!A17="","",MAO_OBRA!A17) | D17: =IF(MAO_OBRA!B17="","",MAO_OBRA!B17) | E17: =MAO_OBRA!O17 | F17: =PARAMETROS!$C$4*(MAO_OBRA!C17*PARAMETROS!$C$18*PARAMETROS!$F$11+MAO_OBRA!D17*PARAMETROS!$C$19*PARAMETROS!$F$12+MAO_OBRA!E17*PARAMETROS!$C$20*PARAMETROS!$F$13) | G17: =F17*PARAMETROS!$C$23*PARAMETROS!$C$24 | H17: =PARAMETROS!$C$22*PARAMETROS!$C$21*E17*PARAMETROS!$C$23*PARAMETROS!$C$24 | I17: =IF(C17="",0,PARAMETROS!$C$25/60*(IF(PARAMETROS!$C$27="Real",SUMPRODUCT((BASE!$E$6:$E$205=C17)*BASE!$P$6:$P$205*BASE!$L$6:$L$205*BASE!$N$6:$N$205),SUMPRODUCT((BASE!$E$6:$E$205=C17)*BASE!$P$6:$P$205*BASE!$L$6:$L$205*BASE!$H$6:$H$205))*PARAMETROS!$C$26+SUMPRODUCT((BASE!$E$6:$E$205=C17)*BASE!$P$6:$P$205*BASE!$L$6:$L$205*BASE!$O$6:$O$205))) | J17: =IF(G17>0,I17/G17,0) | K17: =G17-I17 | L17: =MAX(0,K17) | M17: =MAX(0,-K17) | N17: =M17 | O17: =IF(PARAMETROS!$C$28>0,M17/PARAMETROS!$C$28,0) | P17: =IF(PARAMETROS!$C$8="Nominal",IF(F17>0,I17/F17,0),J17) | Q17: =IF(C17="","",IF(I17=0,"SEM CARGA",IF(OR(G17=0,J17>=PARAMETROS!$C$7),"INSUFICIENTE",IF(J17>=PARAMETROS!$C$6,"ATENÇÃO","OK")))) | R17: =IF(G17+H17>0,I17/(G17+H17),0) | S17: =G17/PARAMETROS!$C$4 | T17: =S17*PARAMETROS!$C$5 | U17: =IF(I17>0,SUMIF(BASE!$E$6:$E$205,C17,BASE!$L$6:$L$205)*PARAMETROS!$C$25*G17/I17,0)
... A20: 1 | B20: 15 | C20: =IF(MAO_OBRA!A20="","",MAO_OBRA!A20) | D20: =IF(MAO_OBRA!B20="","",MAO_OBRA!B20) | E20: =MAO_OBRA!O20 | F20: =PARAMETROS!$C$4*(MAO_OBRA!C20*PARAMETROS!$C$18*PARAMETROS!$F$11+MAO_OBRA!D20*PARAMETROS!$C$19*PARAMETROS!$F$12+MAO_OBRA!E20*PARAMETROS!$C$20*PARAMETROS!$F$13) | G20: =F20*PARAMETROS!$C$23*PARAMETROS!$C$24 | H20: =PARAMETROS!$C$22*PARAMETROS!$C$21*E20*PARAMETROS!$C$23*PARAMETROS!$C$24 | I20: =IF(C20="",0,PARAMETROS!$C$25/60*(IF(PARAMETROS!$C$27="Real",SUMPRODUCT((BASE!$E$6:$E$205=C20)*BASE!$P$6:$P$205*BASE!$L$6:$L$205*BASE!$N$6:$N$205),SUMPRODUCT((BASE!$E$6:$E$205=C20)*BASE!$P$6:$P$205*BASE!$L$6:$L$205*BASE!$H$6:$H$205))*PARAMETROS!$C$26+SUMPRODUCT((BASE!$E$6:$E$205=C20)*BASE!$P$6:$P$205*BASE!$L$6:$L$205*BASE!$O$6:$O$205))) | J20: =IF(G20>0,I20/G20,0) | K20: =G20-I20 | L20: =MAX(0,K20) | M20: =MAX(0,-K20) | N20: =M20 | O20: =IF(PARAMETROS!$C$28>0,M20/PARAMETROS!$C$28,0) | P20: =IF(PARAMETROS!$C$8="Nominal",IF(F20>0,I20/F20,0),J20) | Q20: =IF(C20="","",IF(I20=0,"SEM CARGA",IF(OR(G20=0,J20>=PARAMETROS!$C$7),"INSUFICIENTE",IF(J20>=PARAMETROS!$C$6,"ATENÇÃO","OK")))) | R20: =IF(G20+H20>0,I20/(G20+H20),0) | S20: =G20/PARAMETROS!$C$4 | T20: =S20*PARAMETROS!$C$5 | U20: =IF(I20>0,SUMIF(BASE!$E$6:$E$205,C20,BASE!$L$6:$L$205)*PARAMETROS!$C$25*G20/I20,0)
A21: 2 | B21: 1 | C21: =IF(MAO_OBRA!A6="","",MAO_OBRA!A6) | D21: =IF(MAO_OBRA!B6="","",MAO_OBRA!B6) | E21: =MAO_OBRA!P6 | F21: =PARAMETROS!$C$4*(MAO_OBRA!F6*PARAMETROS!$D$18*PARAMETROS!$F$11+MAO_OBRA!G6*PARAMETROS!$D$19*PARAMETROS!$F$12+MAO_OBRA!H6*PARAMETROS!$D$20*PARAMETROS!$F$13) | G21: =F21*PARAMETROS!$D$23*PARAMETROS!$D$24 | H21: =PARAMETROS!$D$22*PARAMETROS!$D$21*E21*PARAMETROS!$D$23*PARAMETROS!$D$24 | I21: =IF(C21="",0,PARAMETROS!$D$25/60*(IF(PARAMETROS!$D$27="Real",SUMPRODUCT((BASE!$E$6:$E$205=C21)*BASE!$P$6:$P$205*BASE!$L$6:$L$205*BASE!$N$6:$N$205),SUMPRODUCT((BASE!$E$6:$E$205=C21)*BASE!$P$6:$P$205*BASE!$L$6:$L$205*BASE!$H$6:$H$205))*PARAMETROS!$D$26+SUMPRODUCT((BASE!$E$6:$E$205=C21)*BASE!$P$6:$P$205*BASE!$L$6:$L$205*BASE!$O$6:$O$205))) | J21: =IF(G21>0,I21/G21,0) | K21: =G21-I21 | L21: =MAX(0,K21) | M21: =MAX(0,-K21) | N21: =M21 | O21: =IF(PARAMETROS!$D$28>0,M21/PARAMETROS!$D$28,0) | P21: =IF(PARAMETROS!$C$8="Nominal",IF(F21>0,I21/F21,0),J21) | Q21: =IF(C21="","",IF(I21=0,"SEM CARGA",IF(OR(G21=0,J21>=PARAMETROS!$C$7),"INSUFICIENTE",IF(J21>=PARAMETROS!$C$6,"ATENÇÃO","OK")))) | R21: =IF(G21+H21>0,I21/(G21+H21),0) | S21: =G21/PARAMETROS!$C$4 | T21: =S21*PARAMETROS!$C$5 | U21: =IF(I21>0,SUMIF(BASE!$E$6:$E$205,C21,BASE!$L$6:$L$205)*PARAMETROS!$D$25*G21/I21,0)
A22: 2 | B22: 2 | C22: =IF(MAO_OBRA!A7="","",MAO_OBRA!A7) | D22: =IF(MAO_OBRA!B7="","",MAO_OBRA!B7) | E22: =MAO_OBRA!P7 | F22: =PARAMETROS!$C$4*(MAO_OBRA!F7*PARAMETROS!$D$18*PARAMETROS!$F$11+MAO_OBRA!G7*PARAMETROS!$D$19*PARAMETROS!$F$12+MAO_OBRA!H7*PARAMETROS!$D$20*PARAMETROS!$F$13) | G22: =F22*PARAMETROS!$D$23*PARAMETROS!$D$24 | H22: =PARAMETROS!$D$22*PARAMETROS!$D$21*E22*PARAMETROS!$D$23*PARAMETROS!$D$24 | I22: =IF(C22="",0,PARAMETROS!$D$25/60*(IF(PARAMETROS!$D$27="Real",SUMPRODUCT((BASE!$E$6:$E$205=C22)*BASE!$P$6:$P$205*BASE!$L$6:$L$205*BASE!$N$6:$N$205),SUMPRODUCT((BASE!$E$6:$E$205=C22)*BASE!$P$6:$P$205*BASE!$L$6:$L$205*BASE!$H$6:$H$205))*PARAMETROS!$D$26+SUMPRODUCT((BASE!$E$6:$E$205=C22)*BASE!$P$6:$P$205*BASE!$L$6:$L$205*BASE!$O$6:$O$205))) | J22: =IF(G22>0,I22/G22,0) | K22: =G22-I22 | L22: =MAX(0,K22) | M22: =MAX(0,-K22) | N22: =M22 | O22: =IF(PARAMETROS!$D$28>0,M22/PARAMETROS!$D$28,0) | P22: =IF(PARAMETROS!$C$8="Nominal",IF(F22>0,I22/F22,0),J22) | Q22: =IF(C22="","",IF(I22=0,"SEM CARGA",IF(OR(G22=0,J22>=PARAMETROS!$C$7),"INSUFICIENTE",IF(J22>=PARAMETROS!$C$6,"ATENÇÃO","OK")))) | R22: =IF(G22+H22>0,I22/(G22+H22),0) | S22: =G22/PARAMETROS!$C$4 | T22: =S22*PARAMETROS!$C$5 | U22: =IF(I22>0,SUMIF(BASE!$E$6:$E$205,C22,BASE!$L$6:$L$205)*PARAMETROS!$D$25*G22/I22,0)
A23: 2 | B23: 3 | C23: =IF(MAO_OBRA!A8="","",MAO_OBRA!A8) | D23: =IF(MAO_OBRA!B8="","",MAO_OBRA!B8) | E23: =MAO_OBRA!P8 | F23: =PARAMETROS!$C$4*(MAO_OBRA!F8*PARAMETROS!$D$18*PARAMETROS!$F$11+MAO_OBRA!G8*PARAMETROS!$D$19*PARAMETROS!$F$12+MAO_OBRA!H8*PARAMETROS!$D$20*PARAMETROS!$F$13) | G23: =F23*PARAMETROS!$D$23*PARAMETROS!$D$24 | H23: =PARAMETROS!$D$22*PARAMETROS!$D$21*E23*PARAMETROS!$D$23*PARAMETROS!$D$24 | I23: =IF(C23="",0,PARAMETROS!$D$25/60*(IF(PARAMETROS!$D$27="Real",SUMPRODUCT((BASE!$E$6:$E$205=C23)*BASE!$P$6:$P$205*BASE!$L$6:$L$205*BASE!$N$6:$N$205),SUMPRODUCT((BASE!$E$6:$E$205=C23)*BASE!$P$6:$P$205*BASE!$L$6:$L$205*BASE!$H$6:$H$205))*PARAMETROS!$D$26+SUMPRODUCT((BASE!$E$6:$E$205=C23)*BASE!$P$6:$P$205*BASE!$L$6:$L$205*BASE!$O$6:$O$205))) | J23: =IF(G23>0,I23/G23,0) | K23: =G23-I23 | L23: =MAX(0,K23) | M23: =MAX(0,-K23) | N23: =M23 | O23: =IF(PARAMETROS!$D$28>0,M23/PARAMETROS!$D$28,0) | P23: =IF(PARAMETROS!$C$8="Nominal",IF(F23>0,I23/F23,0),J23) | Q23: =IF(C23="","",IF(I23=0,"SEM CARGA",IF(OR(G23=0,J23>=PARAMETROS!$C$7),"INSUFICIENTE",IF(J23>=PARAMETROS!$C$6,"ATENÇÃO","OK")))) | R23: =IF(G23+H23>0,I23/(G23+H23),0) | S23: =G23/PARAMETROS!$C$4 | T23: =S23*PARAMETROS!$C$5 | U23: =IF(I23>0,SUMIF(BASE!$E$6:$E$205,C23,BASE!$L$6:$L$205)*PARAMETROS!$D$25*G23/I23,0)
A24: 2 | B24: 4 | C24: =IF(MAO_OBRA!A9="","",MAO_OBRA!A9) | D24: =IF(MAO_OBRA!B9="","",MAO_OBRA!B9) | E24: =MAO_OBRA!P9 | F24: =PARAMETROS!$C$4*(MAO_OBRA!F9*PARAMETROS!$D$18*PARAMETROS!$F$11+MAO_OBRA!G9*PARAMETROS!$D$19*PARAMETROS!$F$12+MAO_OBRA!H9*PARAMETROS!$D$20*PARAMETROS!$F$13) | G24: =F24*PARAMETROS!$D$23*PARAMETROS!$D$24 | H24: =PARAMETROS!$D$22*PARAMETROS!$D$21*E24*PARAMETROS!$D$23*PARAMETROS!$D$24 | I24: =IF(C24="",0,PARAMETROS!$D$25/60*(IF(PARAMETROS!$D$27="Real",SUMPRODUCT((BASE!$E$6:$E$205=C24)*BASE!$P$6:$P$205*BASE!$L$6:$L$205*BASE!$N$6:$N$205),SUMPRODUCT((BASE!$E$6:$E$205=C24)*BASE!$P$6:$P$205*BASE!$L$6:$L$205*BASE!$H$6:$H$205))*PARAMETROS!$D$26+SUMPRODUCT((BASE!$E$6:$E$205=C24)*BASE!$P$6:$P$205*BASE!$L$6:$L$205*BASE!$O$6:$O$205))) | J24: =IF(G24>0,I24/G24,0) | K24: =G24-I24 | L24: =MAX(0,K24) | M24: =MAX(0,-K24) | N24: =M24 | O24: =IF(PARAMETROS!$D$28>0,M24/PARAMETROS!$D$28,0) | P24: =IF(PARAMETROS!$C$8="Nominal",IF(F24>0,I24/F24,0),J24) | Q24: =IF(C24="","",IF(I24=0,"SEM CARGA",IF(OR(G24=0,J24>=PARAMETROS!$C$7),"INSUFICIENTE",IF(J24>=PARAMETROS!$C$6,"ATENÇÃO","OK")))) | R24: =IF(G24+H24>0,I24/(G24+H24),0) | S24: =G24/PARAMETROS!$C$4 | T24: =S24*PARAMETROS!$C$5 | U24: =IF(I24>0,SUMIF(BASE!$E$6:$E$205,C24,BASE!$L$6:$L$205)*PARAMETROS!$D$25*G24/I24,0)
A25: 2 | B25: 5 | C25: =IF(MAO_OBRA!A10="","",MAO_OBRA!A10) | D25: =IF(MAO_OBRA!B10="","",MAO_OBRA!B10) | E25: =MAO_OBRA!P10 | F25: =PARAMETROS!$C$4*(MAO_OBRA!F10*PARAMETROS!$D$18*PARAMETROS!$F$11+MAO_OBRA!G10*PARAMETROS!$D$19*PARAMETROS!$F$12+MAO_OBRA!H10*PARAMETROS!$D$20*PARAMETROS!$F$13) | G25: =F25*PARAMETROS!$D$23*PARAMETROS!$D$24 | H25: =PARAMETROS!$D$22*PARAMETROS!$D$21*E25*PARAMETROS!$D$23*PARAMETROS!$D$24 | I25: =IF(C25="",0,PARAMETROS!$D$25/60*(IF(PARAMETROS!$D$27="Real",SUMPRODUCT((BASE!$E$6:$E$205=C25)*BASE!$P$6:$P$205*BASE!$L$6:$L$205*BASE!$N$6:$N$205),SUMPRODUCT((BASE!$E$6:$E$205=C25)*BASE!$P$6:$P$205*BASE!$L$6:$L$205*BASE!$H$6:$H$205))*PARAMETROS!$D$26+SUMPRODUCT((BASE!$E$6:$E$205=C25)*BASE!$P$6:$P$205*BASE!$L$6:$L$205*BASE!$O$6:$O$205))) | J25: =IF(G25>0,I25/G25,0) | K25: =G25-I25 | L25: =MAX(0,K25) | M25: =MAX(0,-K25) | N25: =M25 | O25: =IF(PARAMETROS!$D$28>0,M25/PARAMETROS!$D$28,0) | P25: =IF(PARAMETROS!$C$8="Nominal",IF(F25>0,I25/F25,0),J25) | Q25: =IF(C25="","",IF(I25=0,"SEM CARGA",IF(OR(G25=0,J25>=PARAMETROS!$C$7),"INSUFICIENTE",IF(J25>=PARAMETROS!$C$6,"ATENÇÃO","OK")))) | R25: =IF(G25+H25>0,I25/(G25+H25),0) | S25: =G25/PARAMETROS!$C$4 | T25: =S25*PARAMETROS!$C$5 | U25: =IF(I25>0,SUMIF(BASE!$E$6:$E$205,C25,BASE!$L$6:$L$205)*PARAMETROS!$D$25*G25/I25,0)
A26: 2 | B26: 6 | C26: =IF(MAO_OBRA!A11="","",MAO_OBRA!A11) | D26: =IF(MAO_OBRA!B11="","",MAO_OBRA!B11) | E26: =MAO_OBRA!P11 | F26: =PARAMETROS!$C$4*(MAO_OBRA!F11*PARAMETROS!$D$18*PARAMETROS!$F$11+MAO_OBRA!G11*PARAMETROS!$D$19*PARAMETROS!$F$12+MAO_OBRA!H11*PARAMETROS!$D$20*PARAMETROS!$F$13) | G26: =F26*PARAMETROS!$D$23*PARAMETROS!$D$24 | H26: =PARAMETROS!$D$22*PARAMETROS!$D$21*E26*PARAMETROS!$D$23*PARAMETROS!$D$24 | I26: =IF(C26="",0,PARAMETROS!$D$25/60*(IF(PARAMETROS!$D$27="Real",SUMPRODUCT((BASE!$E$6:$E$205=C26)*BASE!$P$6:$P$205*BASE!$L$6:$L$205*BASE!$N$6:$N$205),SUMPRODUCT((BASE!$E$6:$E$205=C26)*BASE!$P$6:$P$205*BASE!$L$6:$L$205*BASE!$H$6:$H$205))*PARAMETROS!$D$26+SUMPRODUCT((BASE!$E$6:$E$205=C26)*BASE!$P$6:$P$205*BASE!$L$6:$L$205*BASE!$O$6:$O$205))) | J26: =IF(G26>0,I26/G26,0) | K26: =G26-I26 | L26: =MAX(0,K26) | M26: =MAX(0,-K26) | N26: =M26 | O26: =IF(PARAMETROS!$D$28>0,M26/PARAMETROS!$D$28,0) | P26: =IF(PARAMETROS!$C$8="Nominal",IF(F26>0,I26/F26,0),J26) | Q26: =IF(C26="","",IF(I26=0,"SEM CARGA",IF(OR(G26=0,J26>=PARAMETROS!$C$7),"INSUFICIENTE",IF(J26>=PARAMETROS!$C$6,"ATENÇÃO","OK")))) | R26: =IF(G26+H26>0,I26/(G26+H26),0) | S26: =G26/PARAMETROS!$C$4 | T26: =S26*PARAMETROS!$C$5 | U26: =IF(I26>0,SUMIF(BASE!$E$6:$E$205,C26,BASE!$L$6:$L$205)*PARAMETROS!$D$25*G26/I26,0)
A27: 2 | B27: 7 | C27: =IF(MAO_OBRA!A12="","",MAO_OBRA!A12) | D27: =IF(MAO_OBRA!B12="","",MAO_OBRA!B12) | E27: =MAO_OBRA!P12 | F27: =PARAMETROS!$C$4*(MAO_OBRA!F12*PARAMETROS!$D$18*PARAMETROS!$F$11+MAO_OBRA!G12*PARAMETROS!$D$19*PARAMETROS!$F$12+MAO_OBRA!H12*PARAMETROS!$D$20*PARAMETROS!$F$13) | G27: =F27*PARAMETROS!$D$23*PARAMETROS!$D$24 | H27: =PARAMETROS!$D$22*PARAMETROS!$D$21*E27*PARAMETROS!$D$23*PARAMETROS!$D$24 | I27: =IF(C27="",0,PARAMETROS!$D$25/60*(IF(PARAMETROS!$D$27="Real",SUMPRODUCT((BASE!$E$6:$E$205=C27)*BASE!$P$6:$P$205*BASE!$L$6:$L$205*BASE!$N$6:$N$205),SUMPRODUCT((BASE!$E$6:$E$205=C27)*BASE!$P$6:$P$205*BASE!$L$6:$L$205*BASE!$H$6:$H$205))*PARAMETROS!$D$26+SUMPRODUCT((BASE!$E$6:$E$205=C27)*BASE!$P$6:$P$205*BASE!$L$6:$L$205*BASE!$O$6:$O$205))) | J27: =IF(G27>0,I27/G27,0) | K27: =G27-I27 | L27: =MAX(0,K27) | M27: =MAX(0,-K27) | N27: =M27 | O27: =IF(PARAMETROS!$D$28>0,M27/PARAMETROS!$D$28,0) | P27: =IF(PARAMETROS!$C$8="Nominal",IF(F27>0,I27/F27,0),J27) | Q27: =IF(C27="","",IF(I27=0,"SEM CARGA",IF(OR(G27=0,J27>=PARAMETROS!$C$7),"INSUFICIENTE",IF(J27>=PARAMETROS!$C$6,"ATENÇÃO","OK")))) | R27: =IF(G27+H27>0,I27/(G27+H27),0) | S27: =G27/PARAMETROS!$C$4 | T27: =S27*PARAMETROS!$C$5 | U27: =IF(I27>0,SUMIF(BASE!$E$6:$E$205,C27,BASE!$L$6:$L$205)*PARAMETROS!$D$25*G27/I27,0)
A28: 2 | B28: 8 | C28: =IF(MAO_OBRA!A13="","",MAO_OBRA!A13) | D28: =IF(MAO_OBRA!B13="","",MAO_OBRA!B13) | E28: =MAO_OBRA!P13 | F28: =PARAMETROS!$C$4*(MAO_OBRA!F13*PARAMETROS!$D$18*PARAMETROS!$F$11+MAO_OBRA!G13*PARAMETROS!$D$19*PARAMETROS!$F$12+MAO_OBRA!H13*PARAMETROS!$D$20*PARAMETROS!$F$13) | G28: =F28*PARAMETROS!$D$23*PARAMETROS!$D$24 | H28: =PARAMETROS!$D$22*PARAMETROS!$D$21*E28*PARAMETROS!$D$23*PARAMETROS!$D$24 | I28: =IF(C28="",0,PARAMETROS!$D$25/60*(IF(PARAMETROS!$D$27="Real",SUMPRODUCT((BASE!$E$6:$E$205=C28)*BASE!$P$6:$P$205*BASE!$L$6:$L$205*BASE!$N$6:$N$205),SUMPRODUCT((BASE!$E$6:$E$205=C28)*BASE!$P$6:$P$205*BASE!$L$6:$L$205*BASE!$H$6:$H$205))*PARAMETROS!$D$26+SUMPRODUCT((BASE!$E$6:$E$205=C28)*BASE!$P$6:$P$205*BASE!$L$6:$L$205*BASE!$O$6:$O$205))) | J28: =IF(G28>0,I28/G28,0) | K28: =G28-I28 | L28: =MAX(0,K28) | M28: =MAX(0,-K28) | N28: =M28 | O28: =IF(PARAMETROS!$D$28>0,M28/PARAMETROS!$D$28,0) | P28: =IF(PARAMETROS!$C$8="Nominal",IF(F28>0,I28/F28,0),J28) | Q28: =IF(C28="","",IF(I28=0,"SEM CARGA",IF(OR(G28=0,J28>=PARAMETROS!$C$7),"INSUFICIENTE",IF(J28>=PARAMETROS!$C$6,"ATENÇÃO","OK")))) | R28: =IF(G28+H28>0,I28/(G28+H28),0) | S28: =G28/PARAMETROS!$C$4 | T28: =S28*PARAMETROS!$C$5 | U28: =IF(I28>0,SUMIF(BASE!$E$6:$E$205,C28,BASE!$L$6:$L$205)*PARAMETROS!$D$25*G28/I28,0)
A29: 2 | B29: 9 | C29: =IF(MAO_OBRA!A14="","",MAO_OBRA!A14) | D29: =IF(MAO_OBRA!B14="","",MAO_OBRA!B14) | E29: =MAO_OBRA!P14 | F29: =PARAMETROS!$C$4*(MAO_OBRA!F14*PARAMETROS!$D$18*PARAMETROS!$F$11+MAO_OBRA!G14*PARAMETROS!$D$19*PARAMETROS!$F$12+MAO_OBRA!H14*PARAMETROS!$D$20*PARAMETROS!$F$13) | G29: =F29*PARAMETROS!$D$23*PARAMETROS!$D$24 | H29: =PARAMETROS!$D$22*PARAMETROS!$D$21*E29*PARAMETROS!$D$23*PARAMETROS!$D$24 | I29: =IF(C29="",0,PARAMETROS!$D$25/60*(IF(PARAMETROS!$D$27="Real",SUMPRODUCT((BASE!$E$6:$E$205=C29)*BASE!$P$6:$P$205*BASE!$L$6:$L$205*BASE!$N$6:$N$205),SUMPRODUCT((BASE!$E$6:$E$205=C29)*BASE!$P$6:$P$205*BASE!$L$6:$L$205*BASE!$H$6:$H$205))*PARAMETROS!$D$26+SUMPRODUCT((BASE!$E$6:$E$205=C29)*BASE!$P$6:$P$205*BASE!$L$6:$L$205*BASE!$O$6:$O$205))) | J29: =IF(G29>0,I29/G29,0) | K29: =G29-I29 | L29: =MAX(0,K29) | M29: =MAX(0,-K29) | N29: =M29 | O29: =IF(PARAMETROS!$D$28>0,M29/PARAMETROS!$D$28,0) | P29: =IF(PARAMETROS!$C$8="Nominal",IF(F29>0,I29/F29,0),J29) | Q29: =IF(C29="","",IF(I29=0,"SEM CARGA",IF(OR(G29=0,J29>=PARAMETROS!$C$7),"INSUFICIENTE",IF(J29>=PARAMETROS!$C$6,"ATENÇÃO","OK")))) | R29: =IF(G29+H29>0,I29/(G29+H29),0) | S29: =G29/PARAMETROS!$C$4 | T29: =S29*PARAMETROS!$C$5 | U29: =IF(I29>0,SUMIF(BASE!$E$6:$E$205,C29,BASE!$L$6:$L$205)*PARAMETROS!$D$25*G29/I29,0)
A30: 2 | B30: 10 | C30: =IF(MAO_OBRA!A15="","",MAO_OBRA!A15) | D30: =IF(MAO_OBRA!B15="","",MAO_OBRA!B15) | E30: =MAO_OBRA!P15 | F30: =PARAMETROS!$C$4*(MAO_OBRA!F15*PARAMETROS!$D$18*PARAMETROS!$F$11+MAO_OBRA!G15*PARAMETROS!$D$19*PARAMETROS!$F$12+MAO_OBRA!H15*PARAMETROS!$D$20*PARAMETROS!$F$13) | G30: =F30*PARAMETROS!$D$23*PARAMETROS!$D$24 | H30: =PARAMETROS!$D$22*PARAMETROS!$D$21*E30*PARAMETROS!$D$23*PARAMETROS!$D$24 | I30: =IF(C30="",0,PARAMETROS!$D$25/60*(IF(PARAMETROS!$D$27="Real",SUMPRODUCT((BASE!$E$6:$E$205=C30)*BASE!$P$6:$P$205*BASE!$L$6:$L$205*BASE!$N$6:$N$205),SUMPRODUCT((BASE!$E$6:$E$205=C30)*BASE!$P$6:$P$205*BASE!$L$6:$L$205*BASE!$H$6:$H$205))*PARAMETROS!$D$26+SUMPRODUCT((BASE!$E$6:$E$205=C30)*BASE!$P$6:$P$205*BASE!$L$6:$L$205*BASE!$O$6:$O$205))) | J30: =IF(G30>0,I30/G30,0) | K30: =G30-I30 | L30: =MAX(0,K30) | M30: =MAX(0,-K30) | N30: =M30 | O30: =IF(PARAMETROS!$D$28>0,M30/PARAMETROS!$D$28,0) | P30: =IF(PARAMETROS!$C$8="Nominal",IF(F30>0,I30/F30,0),J30) | Q30: =IF(C30="","",IF(I30=0,"SEM CARGA",IF(OR(G30=0,J30>=PARAMETROS!$C$7),"INSUFICIENTE",IF(J30>=PARAMETROS!$C$6,"ATENÇÃO","OK")))) | R30: =IF(G30+H30>0,I30/(G30+H30),0) | S30: =G30/PARAMETROS!$C$4 | T30: =S30*PARAMETROS!$C$5 | U30: =IF(I30>0,SUMIF(BASE!$E$6:$E$205,C30,BASE!$L$6:$L$205)*PARAMETROS!$D$25*G30/I30,0)
A31: 2 | B31: 11 | C31: =IF(MAO_OBRA!A16="","",MAO_OBRA!A16) | D31: =IF(MAO_OBRA!B16="","",MAO_OBRA!B16) | E31: =MAO_OBRA!P16 | F31: =PARAMETROS!$C$4*(MAO_OBRA!F16*PARAMETROS!$D$18*PARAMETROS!$F$11+MAO_OBRA!G16*PARAMETROS!$D$19*PARAMETROS!$F$12+MAO_OBRA!H16*PARAMETROS!$D$20*PARAMETROS!$F$13) | G31: =F31*PARAMETROS!$D$23*PARAMETROS!$D$24 | H31: =PARAMETROS!$D$22*PARAMETROS!$D$21*E31*PARAMETROS!$D$23*PARAMETROS!$D$24 | I31: =IF(C31="",0,PARAMETROS!$D$25/60*(IF(PARAMETROS!$D$27="Real",SUMPRODUCT((BASE!$E$6:$E$205=C31)*BASE!$P$6:$P$205*BASE!$L$6:$L$205*BASE!$N$6:$N$205),SUMPRODUCT((BASE!$E$6:$E$205=C31)*BASE!$P$6:$P$205*BASE!$L$6:$L$205*BASE!$H$6:$H$205))*PARAMETROS!$D$26+SUMPRODUCT((BASE!$E$6:$E$205=C31)*BASE!$P$6:$P$205*BASE!$L$6:$L$205*BASE!$O$6:$O$205))) | J31: =IF(G31>0,I31/G31,0) | K31: =G31-I31 | L31: =MAX(0,K31) | M31: =MAX(0,-K31) | N31: =M31 | O31: =IF(PARAMETROS!$D$28>0,M31/PARAMETROS!$D$28,0) | P31: =IF(PARAMETROS!$C$8="Nominal",IF(F31>0,I31/F31,0),J31) | Q31: =IF(C31="","",IF(I31=0,"SEM CARGA",IF(OR(G31=0,J31>=PARAMETROS!$C$7),"INSUFICIENTE",IF(J31>=PARAMETROS!$C$6,"ATENÇÃO","OK")))) | R31: =IF(G31+H31>0,I31/(G31+H31),0) | S31: =G31/PARAMETROS!$C$4 | T31: =S31*PARAMETROS!$C$5 | U31: =IF(I31>0,SUMIF(BASE!$E$6:$E$205,C31,BASE!$L$6:$L$205)*PARAMETROS!$D$25*G31/I31,0)
A32: 2 | B32: 12 | C32: =IF(MAO_OBRA!A17="","",MAO_OBRA!A17) | D32: =IF(MAO_OBRA!B17="","",MAO_OBRA!B17) | E32: =MAO_OBRA!P17 | F32: =PARAMETROS!$C$4*(MAO_OBRA!F17*PARAMETROS!$D$18*PARAMETROS!$F$11+MAO_OBRA!G17*PARAMETROS!$D$19*PARAMETROS!$F$12+MAO_OBRA!H17*PARAMETROS!$D$20*PARAMETROS!$F$13) | G32: =F32*PARAMETROS!$D$23*PARAMETROS!$D$24 | H32: =PARAMETROS!$D$22*PARAMETROS!$D$21*E32*PARAMETROS!$D$23*PARAMETROS!$D$24 | I32: =IF(C32="",0,PARAMETROS!$D$25/60*(IF(PARAMETROS!$D$27="Real",SUMPRODUCT((BASE!$E$6:$E$205=C32)*BASE!$P$6:$P$205*BASE!$L$6:$L$205*BASE!$N$6:$N$205),SUMPRODUCT((BASE!$E$6:$E$205=C32)*BASE!$P$6:$P$205*BASE!$L$6:$L$205*BASE!$H$6:$H$205))*PARAMETROS!$D$26+SUMPRODUCT((BASE!$E$6:$E$205=C32)*BASE!$P$6:$P$205*BASE!$L$6:$L$205*BASE!$O$6:$O$205))) | J32: =IF(G32>0,I32/G32,0) | K32: =G32-I32 | L32: =MAX(0,K32) | M32: =MAX(0,-K32) | N32: =M32 | O32: =IF(PARAMETROS!$D$28>0,M32/PARAMETROS!$D$28,0) | P32: =IF(PARAMETROS!$C$8="Nominal",IF(F32>0,I32/F32,0),J32) | Q32: =IF(C32="","",IF(I32=0,"SEM CARGA",IF(OR(G32=0,J32>=PARAMETROS!$C$7),"INSUFICIENTE",IF(J32>=PARAMETROS!$C$6,"ATENÇÃO","OK")))) | R32: =IF(G32+H32>0,I32/(G32+H32),0) | S32: =G32/PARAMETROS!$C$4 | T32: =S32*PARAMETROS!$C$5 | U32: =IF(I32>0,SUMIF(BASE!$E$6:$E$205,C32,BASE!$L$6:$L$205)*PARAMETROS!$D$25*G32/I32,0)
... A35: 2 | B35: 15 | C35: =IF(MAO_OBRA!A20="","",MAO_OBRA!A20) | D35: =IF(MAO_OBRA!B20="","",MAO_OBRA!B20) | E35: =MAO_OBRA!P20 | F35: =PARAMETROS!$C$4*(MAO_OBRA!F20*PARAMETROS!$D$18*PARAMETROS!$F$11+MAO_OBRA!G20*PARAMETROS!$D$19*PARAMETROS!$F$12+MAO_OBRA!H20*PARAMETROS!$D$20*PARAMETROS!$F$13) | G35: =F35*PARAMETROS!$D$23*PARAMETROS!$D$24 | H35: =PARAMETROS!$D$22*PARAMETROS!$D$21*E35*PARAMETROS!$D$23*PARAMETROS!$D$24 | I35: =IF(C35="",0,PARAMETROS!$D$25/60*(IF(PARAMETROS!$D$27="Real",SUMPRODUCT((BASE!$E$6:$E$205=C35)*BASE!$P$6:$P$205*BASE!$L$6:$L$205*BASE!$N$6:$N$205),SUMPRODUCT((BASE!$E$6:$E$205=C35)*BASE!$P$6:$P$205*BASE!$L$6:$L$205*BASE!$H$6:$H$205))*PARAMETROS!$D$26+SUMPRODUCT((BASE!$E$6:$E$205=C35)*BASE!$P$6:$P$205*BASE!$L$6:$L$205*BASE!$O$6:$O$205))) | J35: =IF(G35>0,I35/G35,0) | K35: =G35-I35 | L35: =MAX(0,K35) | M35: =MAX(0,-K35) | N35: =M35 | O35: =IF(PARAMETROS!$D$28>0,M35/PARAMETROS!$D$28,0) | P35: =IF(PARAMETROS!$C$8="Nominal",IF(F35>0,I35/F35,0),J35) | Q35: =IF(C35="","",IF(I35=0,"SEM CARGA",IF(OR(G35=0,J35>=PARAMETROS!$C$7),"INSUFICIENTE",IF(J35>=PARAMETROS!$C$6,"ATENÇÃO","OK")))) | R35: =IF(G35+H35>0,I35/(G35+H35),0) | S35: =G35/PARAMETROS!$C$4 | T35: =S35*PARAMETROS!$C$5 | U35: =IF(I35>0,SUMIF(BASE!$E$6:$E$205,C35,BASE!$L$6:$L$205)*PARAMETROS!$D$25*G35/I35,0)
A36: 3 | B36: 1 | C36: =IF(MAO_OBRA!A6="","",MAO_OBRA!A6) | D36: =IF(MAO_OBRA!B6="","",MAO_OBRA!B6) | E36: =MAO_OBRA!Q6 | F36: =PARAMETROS!$C$4*(MAO_OBRA!I6*PARAMETROS!$E$18*PARAMETROS!$F$11+MAO_OBRA!J6*PARAMETROS!$E$19*PARAMETROS!$F$12+MAO_OBRA!K6*PARAMETROS!$E$20*PARAMETROS!$F$13) | G36: =F36*PARAMETROS!$E$23*PARAMETROS!$E$24 | H36: =PARAMETROS!$E$22*PARAMETROS!$E$21*E36*PARAMETROS!$E$23*PARAMETROS!$E$24 | I36: =IF(C36="",0,PARAMETROS!$E$25/60*(IF(PARAMETROS!$E$27="Real",SUMPRODUCT((BASE!$E$6:$E$205=C36)*BASE!$P$6:$P$205*BASE!$L$6:$L$205*BASE!$N$6:$N$205),SUMPRODUCT((BASE!$E$6:$E$205=C36)*BASE!$P$6:$P$205*BASE!$L$6:$L$205*BASE!$H$6:$H$205))*PARAMETROS!$E$26+SUMPRODUCT((BASE!$E$6:$E$205=C36)*BASE!$P$6:$P$205*BASE!$L$6:$L$205*BASE!$O$6:$O$205))) | J36: =IF(G36>0,I36/G36,0) | K36: =G36-I36 | L36: =MAX(0,K36) | M36: =MAX(0,-K36) | N36: =M36 | O36: =IF(PARAMETROS!$E$28>0,M36/PARAMETROS!$E$28,0) | P36: =IF(PARAMETROS!$C$8="Nominal",IF(F36>0,I36/F36,0),J36) | Q36: =IF(C36="","",IF(I36=0,"SEM CARGA",IF(OR(G36=0,J36>=PARAMETROS!$C$7),"INSUFICIENTE",IF(J36>=PARAMETROS!$C$6,"ATENÇÃO","OK")))) | R36: =IF(G36+H36>0,I36/(G36+H36),0) | S36: =G36/PARAMETROS!$C$4 | T36: =S36*PARAMETROS!$C$5 | U36: =IF(I36>0,SUMIF(BASE!$E$6:$E$205,C36,BASE!$L$6:$L$205)*PARAMETROS!$E$25*G36/I36,0)
A37: 3 | B37: 2 | C37: =IF(MAO_OBRA!A7="","",MAO_OBRA!A7) | D37: =IF(MAO_OBRA!B7="","",MAO_OBRA!B7) | E37: =MAO_OBRA!Q7 | F37: =PARAMETROS!$C$4*(MAO_OBRA!I7*PARAMETROS!$E$18*PARAMETROS!$F$11+MAO_OBRA!J7*PARAMETROS!$E$19*PARAMETROS!$F$12+MAO_OBRA!K7*PARAMETROS!$E$20*PARAMETROS!$F$13) | G37: =F37*PARAMETROS!$E$23*PARAMETROS!$E$24 | H37: =PARAMETROS!$E$22*PARAMETROS!$E$21*E37*PARAMETROS!$E$23*PARAMETROS!$E$24 | I37: =IF(C37="",0,PARAMETROS!$E$25/60*(IF(PARAMETROS!$E$27="Real",SUMPRODUCT((BASE!$E$6:$E$205=C37)*BASE!$P$6:$P$205*BASE!$L$6:$L$205*BASE!$N$6:$N$205),SUMPRODUCT((BASE!$E$6:$E$205=C37)*BASE!$P$6:$P$205*BASE!$L$6:$L$205*BASE!$H$6:$H$205))*PARAMETROS!$E$26+SUMPRODUCT((BASE!$E$6:$E$205=C37)*BASE!$P$6:$P$205*BASE!$L$6:$L$205*BASE!$O$6:$O$205))) | J37: =IF(G37>0,I37/G37,0) | K37: =G37-I37 | L37: =MAX(0,K37) | M37: =MAX(0,-K37) | N37: =M37 | O37: =IF(PARAMETROS!$E$28>0,M37/PARAMETROS!$E$28,0) | P37: =IF(PARAMETROS!$C$8="Nominal",IF(F37>0,I37/F37,0),J37) | Q37: =IF(C37="","",IF(I37=0,"SEM CARGA",IF(OR(G37=0,J37>=PARAMETROS!$C$7),"INSUFICIENTE",IF(J37>=PARAMETROS!$C$6,"ATENÇÃO","OK")))) | R37: =IF(G37+H37>0,I37/(G37+H37),0) | S37: =G37/PARAMETROS!$C$4 | T37: =S37*PARAMETROS!$C$5 | U37: =IF(I37>0,SUMIF(BASE!$E$6:$E$205,C37,BASE!$L$6:$L$205)*PARAMETROS!$E$25*G37/I37,0)
A38: 3 | B38: 3 | C38: =IF(MAO_OBRA!A8="","",MAO_OBRA!A8) | D38: =IF(MAO_OBRA!B8="","",MAO_OBRA!B8) | E38: =MAO_OBRA!Q8 | F38: =PARAMETROS!$C$4*(MAO_OBRA!I8*PARAMETROS!$E$18*PARAMETROS!$F$11+MAO_OBRA!J8*PARAMETROS!$E$19*PARAMETROS!$F$12+MAO_OBRA!K8*PARAMETROS!$E$20*PARAMETROS!$F$13) | G38: =F38*PARAMETROS!$E$23*PARAMETROS!$E$24 | H38: =PARAMETROS!$E$22*PARAMETROS!$E$21*E38*PARAMETROS!$E$23*PARAMETROS!$E$24 | I38: =IF(C38="",0,PARAMETROS!$E$25/60*(IF(PARAMETROS!$E$27="Real",SUMPRODUCT((BASE!$E$6:$E$205=C38)*BASE!$P$6:$P$205*BASE!$L$6:$L$205*BASE!$N$6:$N$205),SUMPRODUCT((BASE!$E$6:$E$205=C38)*BASE!$P$6:$P$205*BASE!$L$6:$L$205*BASE!$H$6:$H$205))*PARAMETROS!$E$26+SUMPRODUCT((BASE!$E$6:$E$205=C38)*BASE!$P$6:$P$205*BASE!$L$6:$L$205*BASE!$O$6:$O$205))) | J38: =IF(G38>0,I38/G38,0) | K38: =G38-I38 | L38: =MAX(0,K38) | M38: =MAX(0,-K38) | N38: =M38 | O38: =IF(PARAMETROS!$E$28>0,M38/PARAMETROS!$E$28,0) | P38: =IF(PARAMETROS!$C$8="Nominal",IF(F38>0,I38/F38,0),J38) | Q38: =IF(C38="","",IF(I38=0,"SEM CARGA",IF(OR(G38=0,J38>=PARAMETROS!$C$7),"INSUFICIENTE",IF(J38>=PARAMETROS!$C$6,"ATENÇÃO","OK")))) | R38: =IF(G38+H38>0,I38/(G38+H38),0) | S38: =G38/PARAMETROS!$C$4 | T38: =S38*PARAMETROS!$C$5 | U38: =IF(I38>0,SUMIF(BASE!$E$6:$E$205,C38,BASE!$L$6:$L$205)*PARAMETROS!$E$25*G38/I38,0)
A39: 3 | B39: 4 | C39: =IF(MAO_OBRA!A9="","",MAO_OBRA!A9) | D39: =IF(MAO_OBRA!B9="","",MAO_OBRA!B9) | E39: =MAO_OBRA!Q9 | F39: =PARAMETROS!$C$4*(MAO_OBRA!I9*PARAMETROS!$E$18*PARAMETROS!$F$11+MAO_OBRA!J9*PARAMETROS!$E$19*PARAMETROS!$F$12+MAO_OBRA!K9*PARAMETROS!$E$20*PARAMETROS!$F$13) | G39: =F39*PARAMETROS!$E$23*PARAMETROS!$E$24 | H39: =PARAMETROS!$E$22*PARAMETROS!$E$21*E39*PARAMETROS!$E$23*PARAMETROS!$E$24 | I39: =IF(C39="",0,PARAMETROS!$E$25/60*(IF(PARAMETROS!$E$27="Real",SUMPRODUCT((BASE!$E$6:$E$205=C39)*BASE!$P$6:$P$205*BASE!$L$6:$L$205*BASE!$N$6:$N$205),SUMPRODUCT((BASE!$E$6:$E$205=C39)*BASE!$P$6:$P$205*BASE!$L$6:$L$205*BASE!$H$6:$H$205))*PARAMETROS!$E$26+SUMPRODUCT((BASE!$E$6:$E$205=C39)*BASE!$P$6:$P$205*BASE!$L$6:$L$205*BASE!$O$6:$O$205))) | J39: =IF(G39>0,I39/G39,0) | K39: =G39-I39 | L39: =MAX(0,K39) | M39: =MAX(0,-K39) | N39: =M39 | O39: =IF(PARAMETROS!$E$28>0,M39/PARAMETROS!$E$28,0) | P39: =IF(PARAMETROS!$C$8="Nominal",IF(F39>0,I39/F39,0),J39) | Q39: =IF(C39="","",IF(I39=0,"SEM CARGA",IF(OR(G39=0,J39>=PARAMETROS!$C$7),"INSUFICIENTE",IF(J39>=PARAMETROS!$C$6,"ATENÇÃO","OK")))) | R39: =IF(G39+H39>0,I39/(G39+H39),0) | S39: =G39/PARAMETROS!$C$4 | T39: =S39*PARAMETROS!$C$5 | U39: =IF(I39>0,SUMIF(BASE!$E$6:$E$205,C39,BASE!$L$6:$L$205)*PARAMETROS!$E$25*G39/I39,0)
